Workbook

Sheet Muestras Tintas
A1: Id. original muestra | B1: Variedad | C1: Valles | D1: Fundo | E1: Cuartel | F1: Hilera | G1: N° muestra | H1: Fecha muestreo | I1: pH | J1: Brix | K1: N ° Cosecha | L1: NaOH | M1: Acidez Sulfúrica | N1: Acidez Tartárica | O1: Peso muestra | P1: N° bayas | Q1: Peso Baya | R1: Rendimiento
A2: CS26ADOC9-H56-1 | B2: Cabernet Sauvignon | C2: Maipo | D2: SAN ADOLFO | E2: 9 | F2: 56 | G2: =RIGHT(A2,1) -> 1 | H2: 46042 | I2: 2.81 | J2: 15.9 | L2: 24.84 | M2: =L2*0.49 -> 12.1716 | N2: =M2*1.53 -> 18.622548 | O2: 183.28 | P2: 200 | Q2: =O2/P2 -> 0.9164 | R2: =IF(OR(K2="",VALUE(K2)>5),NA(),CHOOSE(VALUE(K2),17667,14967,15967,16975,14561)) -> #N/A | S2: 17667
A3: CS26ADOC9-H56-2 | B3: Cabernet Sauvignon | C3: Maipo | D3: SAN ADOLFO | E3: 9 | F3: 56 | G3: =RIGHT(A3,1) -> 2 | H3: 46048 | I3: 2.97 | J3: 16.6 | L3: 19.26 | M3: =L3*0.49 -> 9.4374 | N3: =M3*1.53 -> 14.439222 | O3: 192.61 | P3: 200 | Q3: =O3/P3 -> 0.96305 | R3: =IF(OR(K3="",VALUE(K3)>5),NA(),CHOOSE(VALUE(K3),17667,14967,15967,16975,14561)) -> #N/A | S3: 14967 | U3: Cosecha comercial tintos
A4: CS26ADOC9-H56-3 | B4: Cabernet Sauvignon | C4: Maipo | D4: SAN ADOLFO | E4: 9 | F4: 56 | G4: =RIGHT(A4,1) -> 3 | H4: 46055 | I4: 3.12 | J4: 17.5 | L4: 15.56 | M4: =L4*0.49 -> 7.6244 | N4: =M4*1.53 -> 11.665332 | O4: 188.87 | P4: 200 | Q4: =O4/P4 -> 0.94435 | R4: =IF(OR(K4="",VALUE(K4)>5),NA(),CHOOSE(VALUE(K4),17667,14967,15967,16975,14561)) -> #N/A | S4: 15967
A5: CS26ADOC9-H56-4 | B5: Cabernet Sauvignon | C5: Maipo | D5: SAN ADOLFO | E5: 9 | F5: 56 | G5: =RIGHT(A5,1) -> 4 | H5: 46062 | I5: 3.14 | J5: 18.2 | L5: 14.72 | M5: =L5*0.49 -> 7.2128 | N5: =M5*1.53 -> 11.035584 | O5: 197.8 | P5: 200 | Q5: =O5/P5 -> 0.989 | R5: =IF(OR(K5="",VALUE(K5)>5),NA(),CHOOSE(VALUE(K5),17667,14967,15967,16975,14561)) -> #N/A | S5: 16975 | U5: Fundo | V5: Cuartel | W5: Variedad | X5: Fecha cosecha
A6: CS26ADOC9-H56-5 | B6: Cabernet Sauvignon | C6: Maipo | D6: SAN ADOLFO | E6: 9 | F6: 56 | G6: =RIGHT(A6,1) -> 5 | H6: 46069 | I6: 3.2 | J6: 20.1 | L6: 10.72 | M6: =L6*0.49 -> 5.2528 | N6: =M6*1.53 -> 8.036784 | O6: 198.3 | P6: 200 | Q6: =O6/P6 -> 0.9915 | R6: =IF(OR(K6="",VALUE(K6)>5),NA(),CHOOSE(VALUE(K6),17667,14967,15967,16975,14561)) -> #N/A | S6: 14561 | U6: Idahue | V6: 36 | W6: CS | X6: 46090
A7: CS26ADOC9-H56-6 | B7: Cabernet Sauvignon | C7: Maipo | D7: SAN ADOLFO | E7: 9 | F7: 56 | G7: =RIGHT(A7,1) -> 6 | H7: 46076 | I7: 3.37 | J7: 21.8 | L7: 9.1 | M7: =L7*0.49 -> 4.459 | N7: =M7*1.53 -> 6.82227 | O7: 186.4 | P7: 200 | Q7: =O7/P7 -> 0.932 | R7: =IF(OR(K7="",VALUE(K7)>5),NA(),CHOOSE(VALUE(K7),17667,14967,15967,16975,14561)) -> #N/A | S7: 18284 | U7: Nilahue | V7: 2 | W7: CS | X7: 46128
A8: CS26ADOC9-H56-7 | B8: Cabernet Sauvignon | C8: Maipo | D8: SAN ADOLFO | E8: 9 | F8: 56 | G8: =RIGHT(A8,1) -> 7 | H8: 46083 | I8: 3.4 | J8: 23 | L8: 9.17 | M8: =L8*0.49 -> 4.4933 | N8: =M8*1.53 -> 6.874749 | O8: 189.7 | P8: 200 | Q8: =O8/P8 -> 0.9485 | R8: =IF(OR(K8="",VALUE(K8)>5),NA(),CHOOSE(VALUE(K8),17667,14967,15967,16975,14561)) -> #N/A | S8: 16273 | U8: Villa Alegre | V8: 13 | W8: CA | X8: 46125
A9: CS26ADOC9-H56-8 | B9: Cabernet Sauvignon | C9: Maipo | D9: SAN ADOLFO | E9: 9 | F9: 56 | G9: =RIGHT(A9,1) -> 8 | H9: 46090 | I9: 3.48 | J9: 24 | L9: 8.75 | M9: =L9*0.49 -> 4.2875 | N9: =M9*1.53 -> 6.559875 | O9: 191.4 | P9: 200 | Q9: =O9/P9 -> 0.957 | R9: =IF(OR(K9="",VALUE(K9)>5),NA(),CHOOSE(VALUE(K9),17667,14967,15967,16975,14561)) -> #N/A | S9: 15455 | U9: Keule | V9: 3 | W9: CS | X9: 46095
A10: CS26ADOC9-H56-9 | B10: Cabernet Sauvignon | C10: Maipo | D10: SAN ADOLFO | E10: 9 | F10: 56 | G10: =RIGHT(A10,1) -> 9 | H10: 46097 | I10: 3.45 | J10: 24.4 | L10: 7.6 | M10: =L10*0.49 -> 3.724 | N10: =M10*1.53 -> 5.69772 | O10: 191.3 | P10: 200 | Q10: =O10/P10 -> 0.9565 | R10: =IF(OR(K10="",VALUE(K10)>5),NA(),CHOOSE(VALUE(K10),17667,14967,15967,16975,14561)) -> #N/A | S10: 13736 | U10: Lourdes | V10: 207 | W10: CS | X10: 46118
A11: CS26ADOC9-H56-10 | B11: Cabernet Sauvignon | C11: Maipo | D11: SAN ADOLFO | E11: 9 | F11: 56 | G11: =RIGHT(A11,2) -> 10 | H11: 46104 | I11: 3.49 | J11: 24.8 | L11: 7.23 | M11: =L11*0.49 -> 3.5427 | N11: =M11*1.53 -> 5.420331 | O11: 198.3 | P11: 200 | Q11: =O11/P11 -> 0.9915 | R11: =IF(OR(K11="",VALUE(K11)>5),NA(),CHOOSE(VALUE(K11),17667,14967,15967,16975,14561)) -> #N/A | S11: 11842 | U11: Lourdes | V11: 171 | W11: CA | X11: 46119
A12: CS26ADOC9-H56-11 | B12: Cabernet Sauvignon | C12: Maipo | D12: SAN ADOLFO | E12: 9 | F12: 56 | G12: =RIGHT(A12,2) -> 11 | H12: 46111 | I12: 3.49 | J12: 25 | L12: 7.03 | M12: =L12*0.49 -> 3.4447 | N12: =M12*1.53 -> 5.270391 | O12: 182.8 | P12: 200 | Q12: =O12/P12 -> 0.914 | R12: =IF(OR(K12="",VALUE(K12)>5),NA(),CHOOSE(VALUE(K12),17667,14967,15967,16975,14561)) -> #N/A | S12: 11974 | U12: Peumo | V12: 93 | W12: CA | X12: 46140
A13: CS26ADOC9-H56-12 | B13: Cabernet Sauvignon | C13: Maipo | D13: SAN ADOLFO | E13: 9 | F13: 56 | G13: =RIGHT(A13,2) -> 12 | H13: 46118 | I13: 3.56 | J13: 26.5 | L13: 6.5 | M13: =L13*0.49 -> 3.185 | N13: =M13*1.53 -> 4.87305 | O13: 186.2 | P13: 200 | Q13: =O13/P13 -> 0.931 | R13: =IF(OR(K13="",VALUE(K13)>5),NA(),CHOOSE(VALUE(K13),17667,14967,15967,16975,14561)) -> #N/A | S13: 16500 | U13: Qta Maipo | V13: 1 | W13: CA | X13: 46132
A14: CS26ADOC9-H56-13 | B14: Cabernet Sauvignon | C14: Maipo | D14: SAN ADOLFO | E14: 9 | F14: 56 | G14: =RIGHT(A14,2) -> 13 | H14: 46125 | I14: 3.53 | J14: 26.1 | L14: 7.64 | M14: =L14*0.49 -> 3.7436 | N14: =M14*1.53 -> 5.727708 | O14: 192.9 | P14: 200 | Q14: =O14/P14 -> 0.9645 | R14: =IF(OR(K14="",VALUE(K14)>5),NA(),CHOOSE(VALUE(K14),17667,14967,15967,16975,14561)) -> #N/A | S14: 17339 | U14: San Adolfo | V14: 9 | W14: CS
A15: CS26ADOC9-H56-14 | B15: Cabernet Sauvignon | C15: Maipo | D15: SAN ADOLFO | E15: 9 | F15: 56 | G15: 14 | H15: 46133 | I15: 4.06 | J15: 25.6 | L15: 4.37 | M15: =L15*0.49 -> 2.1413 | N15: =M15*1.53 -> 3.276189 | O15: 214 | P15: 200 | Q15: =O15/P15 -> 1.07 | R15: =IF(OR(K15="",VALUE(K15)>5),NA(),CHOOSE(VALUE(K15),17667,14967,15967,16975,14561)) -> #N/A | S15: 15944 | U15: Palo Santo | V15: 42 | W15: CA | X15: 46140
A16: CA26QMAC1-SH-1 | B16: Carmenere | C16: Maipo | D16: QUINTA MAIPO | E16: 1 | F16: SH | G16: =RIGHT(A16,1) -> 1 | H16: 46042 | I16: 2.86 | J16: 14.4 | L16: 23.86 | M16: =L16*0.49 -> 11.6914 | N16: =M16*1.53 -> 17.887842 | O16: 198.13 | P16: 200 | Q16: =O16/P16 -> 0.99065 | R16: =IF(OR(K16="",VALUE(K16)>5),NA(),CHOOSE(VALUE(K16),17667,14967,15967,16975,14561)) -> #N/A | S16: 15278 | U16: Quebrada de agua | V16: 40 | W16: CS
A17: CA26QMAC1-SH-2 | B17: Carmenere | C17: Maipo | D17: QUINTA MAIPO | E17: 1 | F17: SH | G17: =RIGHT(A17,1) -> 2 | H17: 46048 | I17: 3.05 | J17: 15.2 | L17: 17.46 | M17: =L17*0.49 -> 8.5554 | N17: =M17*1.53 -> 13.089762 | O17: 213.59 | P17: 200 | Q17: =O17/P17 -> 1.06795 | R17: =IF(OR(K17="",VALUE(K17)>5),NA(),CHOOSE(VALUE(K17),17667,14967,15967,16975,14561)) -> #N/A | S17: 11822 | U17: Rucahue | V17: 24 | W17: CA
A18: CA26QMAC1-SH-3 | B18: Carmenere | C18: Maipo | D18: QUINTA MAIPO | E18: 1 | F18: SH | G18: =RIGHT(A18,1) -> 3 | H18: 46055 | I18: 3.07 | J18: 16.8 | L18: 13.44 | M18: =L18*0.49 -> 6.5856 | N18: =M18*1.53 -> 10.075968 | O18: 236.44 | P18: 200 | Q18: =O18/P18 -> 1.1822 | R18: =IF(OR(K18="",VALUE(K18)>5),NA(),CHOOSE(VALUE(K18),17667,14967,15967,16975,14561)) -> #N/A | S18: 16889
A19: CA26QMAC1-SH-4 | B19: Carmenere | C19: Maipo | D19: QUINTA MAIPO | E19: 1 | F19: SH | G19: =RIGHT(A19,1) -> 4 | H19: 46062 | I19: 3.27 | J19: 18 | L19: 9.94 | M19: =L19*0.49 -> 4.8706 | N19: =M19*1.53 -> 7.452018 | O19: 243.3 | P19: 200 | Q19: =O19/P19 -> 1.2165 | R19: =IF(OR(K19="",VALUE(K19)>5),NA(),CHOOSE(VALUE(K19),17667,14967,15967,16975,14561)) -> #N/A | S19: 8690
A20: CA26QMAC1-SH-5 | B20: Carmenere | C20: Maipo | D20: QUINTA MAIPO | E20: 1 | F20: SH | G20: =RIGHT(A20,1) -> 5 | H20: 46069 | I20: 3.31 | J20: 20.4 | L20: 8.92 | M20: =L20*0.49 -> 4.3708 | N20: =M20*1.53 -> 6.687324 | O20: 240.6 | P20: 200 | Q20: =O20/P20 -> 1.203 | R20: =IF(OR(K20="",VALUE(K20)>5),NA(),CHOOSE(VALUE(K20),17667,14967,15967,16975,14561)) -> #N/A | S20: 8470 | U20: Cosechas proyecto
A21: CA26QMAC1-SH-6 | B21: Carmenere | C21: Maipo | D21: QUINTA MAIPO | E21: 1 | F21: SH | G21: =RIGHT(A21,1) -> 6 | H21: 46076 | I21: 3.45 | J21: 21.4 | L21: 6.9 | M21: =L21*0.49 -> 3.381 | N21: =M21*1.53 -> 5.17293 | O21: 238.3 | P21: 200 | Q21: =O21/P21 -> 1.1915 | R21: =IF(OR(K21="",VALUE(K21)>5),NA(),CHOOSE(VALUE(K21),17667,14967,15967,16975,14561)) -> #N/A | S21: 10567
A22: CA26QMAC1-SH-7 | B22: Carmenere | C22: Maipo | D22: QUINTA MAIPO | E22: 1 | F22: SH | G22: =RIGHT(A22,1) -> 7 | H22: 46083 | I22: 3.5 | J22: 22.2 | L22: 6.45 | M22: =L22*0.49 -> 3.1605 | N22: =M22*1.53 -> 4.835565 | O22: 225.8 | P22: 200 | Q22: =O22/P22 -> 1.129 | R22: =IF(OR(K22="",VALUE(K22)>5),NA(),CHOOSE(VALUE(K22),17667,14967,15967,16975,14561)) -> #N/A | S22: 11354 | U22: Fundo | V22: Cuartel | W22: Variedad | X22: Fecha cosecha
A23: CA26QMAC1-SH-8 | B23: Carmenere | C23: Maipo | D23: QUINTA MAIPO | E23: 1 | F23: SH | G23: =RIGHT(A23,1) -> 8 | H23: 46090 | I23: 3.56 | J23: 23 | L23: 5.76 | M23: =L23*0.49 -> 2.8224 | N23: =M23*1.53 -> 4.318272 | O23: 259.9 | P23: 200 | Q23: =O23/P23 -> 1.2995 | R23: =IF(OR(K23="",VALUE(K23)>5),NA(),CHOOSE(VALUE(K23),17667,14967,15967,16975,14561)) -> #N/A | S23: 11822 | U23: Idahue | V23: 36 | W23: CS | X23: 46085
A24: CA26QMAC1-SH-9 | B24: Carmenere | C24: Maipo | D24: QUINTA MAIPO | E24: 1 | F24: SH | G24: =RIGHT(A24,1) -> 9 | H24: 46097 | I24: 3.63 | J24: 23.5 | L24: 5.09 | M24: =L24*0.49 -> 2.4941 | N24: =M24*1.53 -> 3.815973 | O24: 273.9 | P24: 200 | Q24: =O24/P24 -> 1.3695 | R24: =IF(OR(K24="",VALUE(K24)>5),NA(),CHOOSE(VALUE(K24),17667,14967,15967,16975,14561)) -> #N/A | S24: 12696 | X24: 46099
A25: CA26QMAC1-SH-10 | B25: Carmenere | C25: Maipo | D25: QUINTA MAIPO | E25: 1 | F25: SH | G25: 10 | H25: 46104 | I25: 3.67 | J25: 23.4 | L25: 5.04 | M25: =L25*0.49 -> 2.4696 | N25: =M25*1.53 -> 3.778488 | O25: 258.7 | P25: 200 | Q25: =O25/P25 -> 1.2935 | R25: =IF(OR(K25="",VALUE(K25)>5),NA(),CHOOSE(VALUE(K25),17667,14967,15967,16975,14561)) -> #N/A | S25: 8614 | X25: 46106
A26: CA26QMAC1-SH-11 | B26: Carmenere | C26: Maipo | D26: QUINTA MAIPO | E26: 1 | F26: SH | G26: 11 | H26: 46111 | I26: 3.75 | J26: 23.4 | L26: 4.6 | M26: =L26*0.49 -> 2.254 | N26: =M26*1.53 -> 3.44862 | O26: 267.7 | P26: 200 | Q26: =O26/P26 -> 1.3385 | R26: =IF(OR(K26="",VALUE(K26)>5),NA(),CHOOSE(VALUE(K26),17667,14967,15967,16975,14561)) -> #N/A | S26: 16583 | X26: 46112
A27: CA26QMAC1-SH-12 | B27: Carmenere | C27: Maipo | D27: QUINTA MAIPO | E27: 1 | F27: SH | G27: 12 | H27: 46118 | I27: 3.8 | J27: 24.8 | L27: 4.51 | M27: =L27*0.49 -> 2.2099 | N27: =M27*1.53 -> 3.381147 | O27: 241.4 | P27: 200 | Q27: =O27/P27 -> 1.207 | R27: =IF(OR(K27="",VALUE(K27)>5),NA(),CHOOSE(VALUE(K27),17667,14967,15967,16975,14561)) -> #N/A | S27: 15409 | X27: 46119
A28: CA26QMAC1-SH-13 | B28: Carmenere | C28: Maipo | D28: QUINTA MAIPO | E28: 1 | F28: SH | G28: 13 | H28: 46125 | I28: 3.66 | J28: 24 | L28: 4.85 | M28: =L28*0.49 -> 2.3765 | N28: =M28*1.53 -> 3.636045 | O28: 232 | P28: 200 | Q28: =O28/P28 -> 1.16 | R28: =IF(OR(K28="",VALUE(K28)>5),NA(),CHOOSE(VALUE(K28),17667,14967,15967,16975,14561)) -> #N/A | S28: 13926 | U28: Peumo | V28: 93 | W28: CA | X28: 46093
A29: CA26QMAC1-SH-14 | B29: Carmenere | C29: Maipo | D29: QUINTA MAIPO | E29: 1 | F29: SH | G29: 14 | H29: 46133 | I29: 4.04 | J29: 24.1 | L29: 3.68 | M29: =L29*0.49 -> 1.8032 | N29: =M29*1.53 -> 2.758896 | O29: 252.9 | P29: 200 | Q29: =O29/P29 -> 1.2645 | R29: =IF(OR(K29="",VALUE(K29)>5),NA(),CHOOSE(VALUE(K29),17667,14967,15967,16975,14561)) -> #N/A | S29: 17738 | X29: 46107
A30: CS26IDAC36-H63/76-1 | B30: Cabernet Sauvignon | C30: Colchagua | D30: IDAHUE | E30: 36 | F30: 63/76 | G30: =RIGHT(A30,1) -> 1 | H30: 46035 | I30: 2.59 | J30: 7.9 | L30: 46.26 | M30: =L30*0.49 -> 22.6674 | N30: =M30*1.53 -> 34.681122 | O30: 164.9 | P30: 200 | Q30: =O30/P30 -> 0.8245 | R30: =IF(OR(K30="",VALUE(K30)>5),NA(),CHOOSE(VALUE(K30),17667,14967,15967,16975,14561)) -> #N/A | S30: 20327 | X30: 46113
A31: CS26IDAC36-H63/76-2 | B31: Cabernet Sauvignon | C31: Colchagua | D31: IDAHUE | E31: 36 | F31: 63/76 | G31: =RIGHT(A31,1) -> 2 | H31: 46044 | I31: 2.9 | J31: 16.3 | L31: 21.4 | M31: =L31*0.49 -> 10.486 | N31: =M31*1.53 -> 16.04358 | O31: 196.55 | P31: 200 | Q31: =O31/P31 -> 0.98275 | R31: =IF(OR(K31="",VALUE(K31)>5),NA(),CHOOSE(VALUE(K31),17667,14967,15967,16975,14561)) -> #N/A | S31: 17297 | X31: 46127
A32: CS26IDAC36-H63/76-3 | B32: Cabernet Sauvignon | C32: Colchagua | D32: IDAHUE | E32: 36 | F32: 63/76 | G32: =RIGHT(A32,1) -> 3 | H32: 46050 | I32: 2.99 | J32: 17.2 | L32: 19.34 | M32: =L32*0.49 -> 9.4766 | N32: =M32*1.53 -> 14.499198 | O32: 199.32 | P32: 200 | Q32: =O32/P32 -> 0.9966 | R32: =IF(OR(K32="",VALUE(K32)>5),NA(),CHOOSE(VALUE(K32),17667,14967,15967,16975,14561)) -> #N/A | S32: 14918 | X32: 46141
A33: CS26IDAC36-H63/76-4 | B33: Cabernet Sauvignon | C33: Colchagua | D33: IDAHUE | E33: 36 | F33: 63/76 | G33: =RIGHT(A33,1) -> 4 | H33: 46057 | I33: 3.03 | J33: 17.8 | L33: 14.24 | M33: =L33*0.49 -> 6.9776 | N33: =M33*1.53 -> 10.675728 | O33: 245.6 | P33: 200 | Q33: =O33/P33 -> 1.228 | R33: =IF(OR(K33="",VALUE(K33)>5),NA(),CHOOSE(VALUE(K33),17667,14967,15967,16975,14561)) -> #N/A | S33: 11933 | U33: Villa Alegre | W33: CA | X33: 46086
A34: CS26IDAC36-H63/76-5 | B34: Cabernet Sauvignon | C34: Colchagua | D34: IDAHUE | E34: 36 | F34: 63/76 | G34: =RIGHT(A34,1) -> 5 | H34: 46064 | I34: 3.15 | J34: 20.1 | L34: 12.46 | M34: =L34*0.49 -> 6.1054 | N34: =M34*1.53 -> 9.341262 | O34: 261.6 | P34: 200 | Q34: =O34/P34 -> 1.308 | R34: =IF(OR(K34="",VALUE(K34)>5),NA(),CHOOSE(VALUE(K34),17667,14967,15967,16975,14561)) -> #N/A | S34: 15813 | X34: 46100
A35: CS26IDAC36-H63/76-6 | B35: Cabernet Sauvignon | C35: Colchagua | D35: IDAHUE | E35: 36 | F35: 63/76 | G35: =RIGHT(A35,1) -> 6 | H35: 46071 | I35: 3.21 | J35: 21.8 | L35: 10.98 | M35: =L35*0.49 -> 5.3802 | N35: =M35*1.53 -> 8.231706 | O35: 240.9 | P35: 200 | Q35: =O35/P35 -> 1.2045 | R35: =IF(OR(K35="",VALUE(K35)>5),NA(),CHOOSE(VALUE(K35),17667,14967,15967,16975,14561)) -> #N/A | S35: 13668 | X35: 46108
A36: CS26IDAC36-H63/76-7 | B36: Cabernet Sauvignon | C36: Colchagua | D36: IDAHUE | E36: 36 | F36: 63/76 | G36: =RIGHT(A36,1) -> 7 | H36: 46078 | I36: 3.23 | J36: 23.7 | L36: 9.66 | M36: =L36*0.49 -> 4.7334 | N36: =M36*1.53 -> 7.242102 | O36: 229.3 | P36: 200 | Q36: =O36/P36 -> 1.1465 | R36: =IF(OR(K36="",VALUE(K36)>5),NA(),CHOOSE(VALUE(K36),17667,14967,15967,16975,14561)) -> #N/A | X36: 46114
A37: CS26IDAC36-H63/76-8 | B37: Cabernet Sauvignon | C37: Colchagua | D37: IDAHUE | E37: 36 | F37: 63/76 | G37: =RIGHT(A37,1) -> 8 | H37: 46085 | I37: 3.31 | J37: 24.7 | K37: 1 | L37: 8.7 | M37: =L37*0.49 -> 4.263 | N37: =M37*1.53 -> 6.52239 | O37: 231.6 | P37: 200 | Q37: =O37/P37 -> 1.158 | R37: =IF(OR(K37="",VALUE(K37)>5),NA(),CHOOSE(VALUE(K37),17667,14967,15967,16975,14561)) -> 17667 | X37: 46121
A38: CS26IDAC36-H63/76-9 | B38: Cabernet Sauvignon | C38: Colchagua | D38: IDAHUE | E38: 36 | F38: 63/76 | G38: =RIGHT(A38,1) -> 9 | H38: 46092 | I38: 3.49 | J38: 25.8 | L38: 8.52 | M38: =L38*0.49 -> 4.1748 | N38: =M38*1.53 -> 6.387444 | O38: 225.8 | P38: 200 | Q38: =O38/P38 -> 1.129 | R38: =IF(OR(K38="",VALUE(K38)>5),NA(),CHOOSE(VALUE(K38),17667,14967,15967,16975,14561)) -> #N/A | U38: Keule | W38: CS | X38: 46087
A39: CS26IDAC36-H63/76-10 | B39: Cabernet Sauvignon | C39: Colchagua | D39: IDAHUE | E39: 36 | F39: 63/76 | G39: 10 | H39: 46099 | I39: 3.4 | J39: 25.7 | K39: 2 | L39: 8.02 | M39: =L39*0.49 -> 3.9298 | N39: =M39*1.53 -> 6.012594 | O39: 224.8 | P39: 200 | Q39: =O39/P39 -> 1.124 | R39: =IF(OR(K39="",VALUE(K39)>5),NA(),CHOOSE(VALUE(K39),17667,14967,15967,16975,14561)) -> 14967 | X39: 46108
A40: CS26IDAC36-H63/76-11 | B40: Cabernet Sauvignon | C40: Colchagua | D40: IDAHUE | E40: 36 | F40: 63/76 | G40: 11 | H40: 46106 | I40: 3.36 | J40: 26.2 | K40: 3 | L40: 8.32 | M40: =L40*0.49 -> 4.0768 | N40: =M40*1.53 -> 6.237504 | O40: 201.2 | P40: 200 | Q40: =O40/P40 -> 1.006 | R40: =IF(OR(K40="",VALUE(K40)>5),NA(),CHOOSE(VALUE(K40),17667,14967,15967,16975,14561)) -> 15967 | X40: 46113
...

Sheet CS-Idahue
A2: 2025
A3: Id. original muestra | B3: Variedad | C3: Valle | D3: Fundo | E3: Cuartel | F3: Hilera | G3: Muestreo Fenoles | H3: Muestreo | I3: Fecha | J3: pH | K3: Brix | L3: Acidez Sulfúrica | M3: Acidez Tartárica | N3: Peso Baya
A4: CS25IDAC36-H62/76-1 | B4: Cabernet Sauvignon | C4: Colchagua | D4: IDAHUE | E4: 36 | F4: 62/76 | H4: 1 | I4: 45691 | J4: 2.75 | K4: 16.2 | L4: 11.2014 | M4: 17.1381 | N4: 1.1
A5: CS25IDAC36-H62/76-2 | B5: Cabernet Sauvignon | C5: Colchagua | D5: IDAHUE | E5: 36 | F5: 62/76 | H5: 2 | I5: 45698 | J5: 2.87 | K5: 17.8 | L5: 8.6436 | M5: 13.2247 | N5: 1.18
A6: CS25IDAC36-H62/76-3 | B6: Cabernet Sauvignon | C6: Colchagua | D6: IDAHUE | E6: 36 | F6: 62/76 | H6: 3 | I6: 45705 | J6: 2.98 | K6: 19 | L6: 7.0364 | M6: 10.7657 | N6: 1.25
A7: CS25IDAC36-H62/76-4 | B7: Cabernet Sauvignon | C7: Colchagua | D7: IDAHUE | E7: 36 | F7: 62/76 | G7: 45712 | H7: 4 | I7: 45712 | J7: 3.08 | K7: 20 | L7: 6.5856 | M7: 10.076 | N7: 1.48
A8: CS25IDAC36-H62/76-5 | B8: Cabernet Sauvignon | C8: Colchagua | D8: IDAHUE | E8: 36 | F8: 62/76 | H8: 5 | I8: 45719 | J8: 3.19 | K8: 21.3 | L8: 5.4488 | M8: 8.3367 | N8: 1.43
A9: CS25IDAC36-H62/76-6 | B9: Cabernet Sauvignon | C9: Colchagua | D9: IDAHUE | E9: 36 | F9: 62/76 | H9: 6 | I9: 45726 | J9: 3.29 | K9: 22.2 | L9: 4.8412 | M9: 7.407 | N9: 1.52
A10: CS25IDAC36-H62/76-7 | B10: Cabernet Sauvignon | C10: Colchagua | D10: IDAHUE | E10: 36 | F10: 62/76 | G10: 45733 | H10: 7 | I10: 45733 | J10: 3.4 | K10: 23.2 | L10: 4.1944 | M10: 6.4174 | N10: 1.52
A11: CS25IDAC36-H62/76-8 | B11: Cabernet Sauvignon | C11: Colchagua | D11: IDAHUE | E11: 36 | F11: 62/76 | G11: 45737 | H11: 8 | I11: 45737 | J11: 3.83 | K11: 23.6 | L11: 3.087 | M11: 4.7231 | N11: 1.65
A12: CS25IDAC36-H62/76-9 | B12: Cabernet Sauvignon | C12: Colchagua | D12: IDAHUE | E12: 36 | F12: 62/76 | G12: 45744 | H12: 9 | I12: 45744 | J12: 3.7 | K12: 24.2 | L12: 3.0233 | M12: 4.6256 | N12: 1.35
A13: CS25IDAC36-H62/76-10 | B13: Cabernet Sauvignon | C13: Colchagua | D13: IDAHUE | E13: 36 | F13: 62/76 | G13: 45751 | H13: 10 | I13: 45751 | J13: 3.81 | K13: 24.8 | L13: 2.7244 | M13: 4.1683 | N13: 1.46
A14: CS25IDAC36-H62/76-11 | B14: Cabernet Sauvignon | C14: Colchagua | D14: IDAHUE | E14: 36 | F14: 62/76 | G14: 45758 | H14: 11 | I14: 45758 | J14: 3.85 | K14: 25.3 | L14: 2.6754 | M14: 4.0934 | N14: 1.53
A16: 2026
A17: Id. original muestra | B17: Variedad | C17: Valle | D17: Fundo | E17: Cuartel | F17: Hilera | G17: Muestreo Fenoles | H17: Muestreo | I17: Fecha | J17: pH | K17: Brix | L17: Acidez Sulfúrica | M17: Acidez Tartárica | N17: Peso Baya | O17: COSECHA
A18: ='Muestras Tintas'!A30 -> CS26IDAC36-H63/76-1 | B18: ='Muestras Tintas'!B30 -> Cabernet Sauvignon | C18: ='Muestras Tintas'!C30 -> Colchagua | D18: ='Muestras Tintas'!D30 -> IDAHUE | E18: ='Muestras Tintas'!E30 -> 36 | F18: ='Muestras Tintas'!F30 -> 63/76 | H18: ='Muestras Tintas'!G30 -> 1 | I18: ='Muestras Tintas'!H30 -> 46035 | J18: ='Muestras Tintas'!I30 -> 2.59 | K18: ='Muestras Tintas'!J30 -> 7.9 | L18: ='Muestras Tintas'!L30*0.49 -> 22.6674 | M18: ='Muestras Tintas'!M30*1.53 -> 34.681122 | N18: ='Muestras Tintas'!O30/200 -> 0.8245
A19: ='Muestras Tintas'!A31 -> CS26IDAC36-H63/76-2 | B19: ='Muestras Tintas'!B31 -> Cabernet Sauvignon | C19: ='Muestras Tintas'!C31 -> Colchagua | D19: ='Muestras Tintas'!D31 -> IDAHUE | E19: ='Muestras Tintas'!E31 -> 36 | F19: ='Muestras Tintas'!F31 -> 63/76 | H19: ='Muestras Tintas'!G31 -> 2 | I19: ='Muestras Tintas'!H31 -> 46044 | J19: ='Muestras Tintas'!I31 -> 2.9 | K19: ='Muestras Tintas'!J31 -> 16.3 | L19: ='Muestras Tintas'!L31*0.49 -> 10.486 | M19: ='Muestras Tintas'!M31*1.53 -> 16.04358 | N19: ='Muestras Tintas'!O31/200 -> 0.98275
A20: ='Muestras Tintas'!A32 -> CS26IDAC36-H63/76-3 | B20: ='Muestras Tintas'!B32 -> Cabernet Sauvignon | C20: ='Muestras Tintas'!C32 -> Colchagua | D20: ='Muestras Tintas'!D32 -> IDAHUE | E20: ='Muestras Tintas'!E32 -> 36 | F20: ='Muestras Tintas'!F32 -> 63/76 | H20: ='Muestras Tintas'!G32 -> 3 | I20: ='Muestras Tintas'!H32 -> 46050 | J20: ='Muestras Tintas'!I32 -> 2.99 | K20: ='Muestras Tintas'!J32 -> 17.2 | L20: ='Muestras Tintas'!L32*0.49 -> 9.4766 | M20: ='Muestras Tintas'!M32*1.53 -> 14.499198 | N20: ='Muestras Tintas'!O32/200 -> 0.9966
A21: ='Muestras Tintas'!A33 -> CS26IDAC36-H63/76-4 | B21: ='Muestras Tintas'!B33 -> Cabernet Sauvignon | C21: ='Muestras Tintas'!C33 -> Colchagua | D21: ='Muestras Tintas'!D33 -> IDAHUE | E21: ='Muestras Tintas'!E33 -> 36 | F21: ='Muestras Tintas'!F33 -> 63/76 | H21: ='Muestras Tintas'!G33 -> 4 | I21: ='Muestras Tintas'!H33 -> 46057 | J21: ='Muestras Tintas'!I33 -> 3.03 | K21: ='Muestras Tintas'!J33 -> 17.8 | L21: ='Muestras Tintas'!L33*0.49 -> 6.9776 | M21: ='Muestras Tintas'!M33*1.53 -> 10.675728 | N21: ='Muestras Tintas'!O33/200 -> 1.228
A22: ='Muestras Tintas'!A34 -> CS26IDAC36-H63/76-5 | B22: ='Muestras Tintas'!B34 -> Cabernet Sauvignon | C22: ='Muestras Tintas'!C34 -> Colchagua | D22: ='Muestras Tintas'!D34 -> IDAHUE | E22: ='Muestras Tintas'!E34 -> 36 | F22: ='Muestras Tintas'!F34 -> 63/76 | H22: ='Muestras Tintas'!G34 -> 5 | I22: ='Muestras Tintas'!H34 -> 46064 | J22: ='Muestras Tintas'!I34 -> 3.15 | K22: ='Muestras Tintas'!J34 -> 20.1 | L22: ='Muestras Tintas'!L34*0.49 -> 6.1054 | M22: ='Muestras Tintas'!M34*1.53 -> 9.341262 | N22: ='Muestras Tintas'!O34/200 -> 1.308
A23: ='Muestras Tintas'!A35 -> CS26IDAC36-H63/76-6 | B23: ='Muestras Tintas'!B35 -> Cabernet Sauvignon | C23: ='Muestras Tintas'!C35 -> Colchagua | D23: ='Muestras Tintas'!D35 -> IDAHUE | E23: ='Muestras Tintas'!E35 -> 36 | F23: ='Muestras Tintas'!F35 -> 63/76 | H23: ='Muestras Tintas'!G35 -> 6 | I23: ='Muestras Tintas'!H35 -> 46071 | J23: ='Muestras Tintas'!I35 -> 3.21 | K23: ='Muestras Tintas'!J35 -> 21.8 | L23: ='Muestras Tintas'!L35*0.49 -> 5.3802 | M23: ='Muestras Tintas'!M35*1.53 -> 8.231706 | N23: ='Muestras Tintas'!O35/200 -> 1.2045
A24: ='Muestras Tintas'!A36 -> CS26IDAC36-H63/76-7 | B24: ='Muestras Tintas'!B36 -> Cabernet Sauvignon | C24: ='Muestras Tintas'!C36 -> Colchagua | D24: ='Muestras Tintas'!D36 -> IDAHUE | E24: ='Muestras Tintas'!E36 -> 36 | F24: ='Muestras Tintas'!F36 -> 63/76 | H24: ='Muestras Tintas'!G36 -> 7 | I24: ='Muestras Tintas'!H36 -> 46078 | J24: ='Muestras Tintas'!I36 -> 3.23 | K24: ='Muestras Tintas'!J36 -> 23.7 | L24: ='Muestras Tintas'!L36*0.49 -> 4.7334 | M24: ='Muestras Tintas'!M36*1.53 -> 7.242102 | N24: ='Muestras Tintas'!O36/200 -> 1.1465
A25: ='Muestras Tintas'!A37 -> CS26IDAC36-H63/76-8 | B25: ='Muestras Tintas'!B37 -> Cabernet Sauvignon | C25: ='Muestras Tintas'!C37 -> Colchagua | D25: ='Muestras Tintas'!D37 -> IDAHUE | E25: ='Muestras Tintas'!E37 -> 36 | F25: ='Muestras Tintas'!F37 -> 63/76 | H25: ='Muestras Tintas'!G37 -> 8 | I25: ='Muestras Tintas'!H37 -> 46085 | J25: ='Muestras Tintas'!I37 -> 3.31 | K25: ='Muestras Tintas'!J37 -> 24.7 | L25: ='Muestras Tintas'!L37*0.49 -> 4.263 | M25: ='Muestras Tintas'!M37*1.53 -> 6.52239 | N25: ='Muestras Tintas'!O37/200 -> 1.158 | O25: 1
A26: ='Muestras Tintas'!A38 -> CS26IDAC36-H63/76-9 | B26: ='Muestras Tintas'!B38 -> Cabernet Sauvignon | C26: ='Muestras Tintas'!C38 -> Colchagua | D26: ='Muestras Tintas'!D38 -> IDAHUE | E26: ='Muestras Tintas'!E38 -> 36 | F26: ='Muestras Tintas'!F38 -> 63/76 | H26: ='Muestras Tintas'!G38 -> 9 | I26: ='Muestras Tintas'!H38 -> 46092 | J26: ='Muestras Tintas'!I38 -> 3.49 | K26: ='Muestras Tintas'!J38 -> 25.8 | L26: ='Muestras Tintas'!L38*0.49 -> 4.1748 | M26: ='Muestras Tintas'!M38*1.53 -> 6.387444 | N26: ='Muestras Tintas'!O38/200 -> 1.129
A27: ='Muestras Tintas'!A39 -> CS26IDAC36-H63/76-10 | B27: ='Muestras Tintas'!B39 -> Cabernet Sauvignon | C27: ='Muestras Tintas'!C39 -> Colchagua | D27: ='Muestras Tintas'!D39 -> IDAHUE | E27: ='Muestras Tintas'!E39 -> 36 | F27: ='Muestras Tintas'!F39 -> 63/76 | H27: ='Muestras Tintas'!G39 -> 10 | I27: ='Muestras Tintas'!H39 -> 46099 | J27: ='Muestras Tintas'!I39 -> 3.4 | K27: ='Muestras Tintas'!J39 -> 25.7 | L27: ='Muestras Tintas'!L39*0.49 -> 3.9298 | M27: ='Muestras Tintas'!M39*1.53 -> 6.012594 | N27: ='Muestras Tintas'!O39/200 -> 1.124 | O27: 2
A28: ='Muestras Tintas'!A40 -> CS26IDAC36-H63/76-11 | B28: ='Muestras Tintas'!B40 -> Cabernet Sauvignon | C28: ='Muestras Tintas'!C40 -> Colchagua | D28: ='Muestras Tintas'!D40 -> IDAHUE | E28: ='Muestras Tintas'!E40 -> 36 | F28: ='Muestras Tintas'!F40 -> 63/76 | H28: ='Muestras Tintas'!G40 -> 11 | I28: ='Muestras Tintas'!H40 -> 46106 | J28: ='Muestras Tintas'!I40 -> 3.36 | K28: ='Muestras Tintas'!J40 -> 26.2 | L28: ='Muestras Tintas'!L40*0.49 -> 4.0768 | M28: ='Muestras Tintas'!M40*1.53 -> 6.237504 | N28: ='Muestras Tintas'!O40/200 -> 1.006
A29: ='Muestras Tintas'!A41 -> CS26IDAC36-H63/76-12 | B29: ='Muestras Tintas'!B41 -> Cabernet Sauvignon | C29: ='Muestras Tintas'!C41 -> Colchagua | D29: ='Muestras Tintas'!D41 -> IDAHUE | E29: ='Muestras Tintas'!E41 -> 36 | F29: ='Muestras Tintas'!F41 -> 63/76 | H29: ='Muestras Tintas'!G41 -> 12 | I29: ='Muestras Tintas'!H41 -> 46112 | J29: ='Muestras Tintas'!I41 -> 3.25 | K29: ='Muestras Tintas'!J41 -> 25.9 | L29: ='Muestras Tintas'!L41*0.49 -> 4.1062 | M29: ='Muestras Tintas'!M41*1.53 -> 6.282486 | N29: ='Muestras Tintas'!O41/200 -> 1.087
A30: ='Muestras Tintas'!A42 -> CS26IDAC36-H63/76-13 | B30: ='Muestras Tintas'!B42 -> Cabernet Sauvignon | C30: ='Muestras Tintas'!C42 -> Colchagua | D30: ='Muestras Tintas'!D42 -> IDAHUE | E30: ='Muestras Tintas'!E42 -> 36 | F30: ='Muestras Tintas'!F42 -> 63/76 | H30: ='Muestras Tintas'!G42 -> 13 | I30: ='Muestras Tintas'!H42 -> 46119 | J30: ='Muestras Tintas'!I42 -> 3.55 | K30: ='Muestras Tintas'!J42 -> 24.5 | L30: ='Muestras Tintas'!L42*0.49 -> 4.0572 | M30: ='Muestras Tintas'!M42*1.53 -> 6.207516 | N30: ='Muestras Tintas'!O42/200 -> 1.288

Sheet CS-Nilahue
A2: 2025
A3: Id. original muestra | B3: Variedad | C3: Valle | D3: Fundo | E3: Cuartel | F3: Hilera | G3: Muestreo Fenoles | H3: Muestreo | I3: Fecha | J3: pH | K3: Brix | L3: Acidez Sulfúrica | M3: Acidez Tartárica | N3: Peso Baya
A4: CS25NILC2-H61/64-1 | B4: Cabernet Sauvignon | C4: Colchagua | D4: NILAHUE | E4: 2 | F4: 61/64 | H4: 1 | I4: 45692 | J4: 2.64 | K4: 16.3 | L4: 12.2402 | M4: 18.7275 | N4: 1.06
A5: CS25NILC2-H61/64-2 | B5: Cabernet Sauvignon | C5: Colchagua | D5: NILAHUE | E5: 2 | F5: 61/64 | H5: 2 | I5: 45699 | J5: 2.77 | K5: 17.2 | L5: 9.2904 | M5: 14.2143 | N5: 1.28
A6: CS25NILC2-H61/64-3 | B6: Cabernet Sauvignon | C6: Colchagua | D6: NILAHUE | E6: 2 | F6: 61/64 | H6: 3 | I6: 45706 | J6: 2.92 | K6: 18.6 | L6: 7.9184 | M6: 12.1152 | N6: 1.29
A7: CS25NILC2-H61/64-4 | B7: Cabernet Sauvignon | C7: Colchagua | D7: NILAHUE | E7: 2 | F7: 61/64 | H7: 4 | I7: 45713 | J7: 3.05 | K7: 19.3 | L7: 6.9188 | M7: 10.5858 | N7: 1.55
A8: CS25NILC2-H61/64-5 | B8: Cabernet Sauvignon | C8: Colchagua | D8: NILAHUE | E8: 2 | F8: 61/64 | H8: 5 | I8: 45720 | J8: 3.19 | K8: 21.8 | L8: 5.3704 | M8: 8.2167 | N8: 1.56
A9: CS25NILC2-H61/64-6 | B9: Cabernet Sauvignon | C9: Colchagua | D9: NILAHUE | E9: 2 | F9: 61/64 | G9: 45727 | H9: 6 | I9: 45727 | J9: 3.28 | K9: 21.9 | L9: 5.3606 | M9: 8.2017 | N9: 1.67
A10: CS25NILC2-H61/64-7 | B10: Cabernet Sauvignon | C10: Colchagua | D10: NILAHUE | E10: 2 | F10: 61/64 | G10: 45734 | H10: 7 | I10: 45734 | J10: 3.4 | K10: 22.4 | L10: 4.7553 | M10: 7.2721 | N10: 1.68
A11: CS25NILC2-H61/64-8 | B11: Cabernet Sauvignon | C11: Colchagua | D11: NILAHUE | E11: 2 | F11: 61/64 | G11: 45742 | H11: 8 | I11: 45742 | J11: 3.41 | K11: 23 | L11: 4.6403 | M11: 7.0997 | N11: 1.74
A12: CS25NILC2-H61/64-9 | B12: Cabernet Sauvignon | C12: Colchagua | D12: NILAHUE | E12: 2 | F12: 61/64 | G12: 45748 | H12: 9 | I12: 45748 | J12: 3.58 | K12: 23.9 | L12: 3.4398 | M12: 5.2629 | N12: 2.11
A13: CS25NILC2-H61/64-10 | B13: Cabernet Sauvignon | C13: Colchagua | D13: NILAHUE | E13: 2 | F13: 61/64 | G13: 45755 | H13: 10 | I13: 45755 | J13: 3.46 | K13: 23.9 | L13: 3.4153 | M13: 5.2254 | N13: 1.7
A14: CS25NILC2-H61/64-11 | B14: Cabernet Sauvignon | C14: Colchagua | D14: NILAHUE | E14: 2 | F14: 61/64 | G14: 45762 | H14: 11 | I14: 45762 | J14: 3.47 | K14: 24.4 | L14: 3.3418 | M14: 5.113 | N14: 1.62
A15: CS25NILC2-H61/64-12 | B15: Cabernet Sauvignon | C15: Colchagua | D15: NILAHUE | E15: 2 | F15: 61/64 | G15: 45777 | H15: 12 | I15: 45777 | J15: 3.64 | K15: 24.6 | L15: 3.3124 | M15: 5.068 | N15: 1.71
A17: 2026
A18: Id. original muestra | B18: Variedad | C18: Valle | D18: Fundo | E18: Cuartel | F18: Hilera | G18: Muestreo Fenoles | H18: Muestreo | I18: Fecha | J18: pH | K18: Brix | L18: Acidez Sulfúrica | M18: Acidez Tartárica | N18: Peso Baya | O18: COSECHA
A19: ='Muestras Tintas'!A43 -> CS26NILC2-H61/66-1 | B19: ='Muestras Tintas'!B43 -> Cabernet Sauvignon | C19: ='Muestras Tintas'!C43 -> Colchagua | D19: ='Muestras Tintas'!D43 -> NILAHUE | E19: ='Muestras Tintas'!E43 -> 2 | F19: ='Muestras Tintas'!F43 -> 61/66 | H19: ='Muestras Tintas'!G43 -> 1 | I19: ='Muestras Tintas'!H43 -> 46043 | J19: ='Muestras Tintas'!I43 -> 2.79 | K19: ='Muestras Tintas'!J43 -> 13.5 | L19: ='Muestras Tintas'!L43*0.49 -> 12.7106 | M19: ='Muestras Tintas'!M43*1.53 -> 19.447218 | N19: ='Muestras Tintas'!O43/200 -> 1.05525
A20: ='Muestras Tintas'!A44 -> CS26NILC2-H61/66-2 | B20: ='Muestras Tintas'!B44 -> Cabernet Sauvignon | C20: ='Muestras Tintas'!C44 -> Colchagua | D20: ='Muestras Tintas'!D44 -> NILAHUE | E20: ='Muestras Tintas'!E44 -> 2 | F20: ='Muestras Tintas'!F44 -> 61/66 | H20: ='Muestras Tintas'!G44 -> 2 | I20: ='Muestras Tintas'!H44 -> 46049 | J20: ='Muestras Tintas'!I44 -> 2.77 | K20: ='Muestras Tintas'!J44 -> 15 | L20: ='Muestras Tintas'!L44*0.49 -> 15.4154 | M20: ='Muestras Tintas'!M44*1.53 -> 23.585562 | N20: ='Muestras Tintas'!O44/200 -> 1.07395
A21: ='Muestras Tintas'!A45 -> CS26NILC2-H61/66-3 | B21: ='Muestras Tintas'!B45 -> Cabernet Sauvignon | C21: ='Muestras Tintas'!C45 -> Colchagua | D21: ='Muestras Tintas'!D45 -> NILAHUE | E21: ='Muestras Tintas'!E45 -> 2 | F21: ='Muestras Tintas'!F45 -> 61/66 | H21: ='Muestras Tintas'!G45 -> 3 | I21: ='Muestras Tintas'!H45 -> 46056 | J21: ='Muestras Tintas'!I45 -> 2.86 | K21: ='Muestras Tintas'!J45 -> 15.5 | L21: ='Muestras Tintas'!L45*0.49 -> 12.6028 | M21: ='Muestras Tintas'!M45*1.53 -> 19.282284 | N21: ='Muestras Tintas'!O45/200 -> 1.18475
A22: ='Muestras Tintas'!A46 -> CS26NILC2-H61/66-4 | B22: ='Muestras Tintas'!B46 -> Cabernet Sauvignon | C22: ='Muestras Tintas'!C46 -> Colchagua | D22: ='Muestras Tintas'!D46 -> NILAHUE | E22: ='Muestras Tintas'!E46 -> 2 | F22: ='Muestras Tintas'!F46 -> 61/66 | H22: ='Muestras Tintas'!G46 -> 4 | I22: ='Muestras Tintas'!H46 -> 46063 | J22: ='Muestras Tintas'!I46 -> 3.11 | K22: ='Muestras Tintas'!J46 -> 18.2 | L22: ='Muestras Tintas'!L46*0.49 -> 9.3688 | M22: ='Muestras Tintas'!M46*1.53 -> 14.334264 | N22: ='Muestras Tintas'!O46/200 -> 1.3675
A23: ='Muestras Tintas'!A47 -> CS26NILC2-H61/66-5 | B23: ='Muestras Tintas'!B47 -> Cabernet Sauvignon | C23: ='Muestras Tintas'!C47 -> Colchagua | D23: ='Muestras Tintas'!D47 -> NILAHUE | E23: ='Muestras Tintas'!E47 -> 2 | F23: ='Muestras Tintas'!F47 -> 61/66 | H23: ='Muestras Tintas'!G47 -> 5 | I23: ='Muestras Tintas'!H47 -> 46070 | J23: ='Muestras Tintas'!I47 -> 3.13 | K23: ='Muestras Tintas'!J47 -> 20 | L23: ='Muestras Tintas'!L47*0.49 -> 8.085 | M23: ='Muestras Tintas'!M47*1.53 -> 12.37005 | N23: ='Muestras Tintas'!O47/200 -> 1.3895
A24: ='Muestras Tintas'!A48 -> CS26NILC2-H61/66-6 | B24: ='Muestras Tintas'!B48 -> Cabernet Sauvignon | C24: ='Muestras Tintas'!C48 -> Colchagua | D24: ='Muestras Tintas'!D48 -> NILAHUE | E24: ='Muestras Tintas'!E48 -> 2 | F24: ='Muestras Tintas'!F48 -> 61/66 | H24: ='Muestras Tintas'!G48 -> 6 | I24: ='Muestras Tintas'!H48 -> 46077 | J24: ='Muestras Tintas'!I48 -> 3.1 | K24: ='Muestras Tintas'!J48 -> 20.7 | L24: ='Muestras Tintas'!L48*0.49 -> 7.203 | M24: ='Muestras Tintas'!M48*1.53 -> 11.02059 | N24: ='Muestras Tintas'!O48/200 -> 1.4555
A25: ='Muestras Tintas'!A49 -> CS26NILC2-H61/66-7 | B25: ='Muestras Tintas'!B49 -> Cabernet Sauvignon | C25: ='Muestras Tintas'!C49 -> Colchagua | D25: ='Muestras Tintas'!D49 -> NILAHUE | E25: ='Muestras Tintas'!E49 -> 2 | F25: ='Muestras Tintas'!F49 -> 61/66 | H25: ='Muestras Tintas'!G49 -> 7 | I25: ='Muestras Tintas'!H49 -> 46084 | J25: ='Muestras Tintas'!I49 -> 3.14 | K25: ='Muestras Tintas'!J49 -> 21.8 | L25: ='Muestras Tintas'!L49*0.49 -> 6.7032 | M25: ='Muestras Tintas'!M49*1.53 -> 10.255896 | N25: ='Muestras Tintas'!O49/200 -> 1.4715
A26: ='Muestras Tintas'!A50 -> CS26NILC2-H61/66-8 | B26: ='Muestras Tintas'!B50 -> Cabernet Sauvignon | C26: ='Muestras Tintas'!C50 -> Colchagua | D26: ='Muestras Tintas'!D50 -> NILAHUE | E26: ='Muestras Tintas'!E50 -> 2 | F26: ='Muestras Tintas'!F50 -> 61/66 | H26: ='Muestras Tintas'!G50 -> 8 | I26: ='Muestras Tintas'!H50 -> 46091 | J26: ='Muestras Tintas'!I50 -> 3.07 | K26: ='Muestras Tintas'!J50 -> 22.4 | L26: ='Muestras Tintas'!L50*0.49 -> 5.5566 | M26: ='Muestras Tintas'!M50*1.53 -> 8.501598 | N26: ='Muestras Tintas'!O50/200 -> 1.438
A27: ='Muestras Tintas'!A51 -> CS26NILC2-H61/66-9 | B27: ='Muestras Tintas'!B51 -> Cabernet Sauvignon | C27: ='Muestras Tintas'!C51 -> Colchagua | D27: ='Muestras Tintas'!D51 -> NILAHUE | E27: ='Muestras Tintas'!E51 -> 2 | F27: ='Muestras Tintas'!F51 -> 61/66 | H27: ='Muestras Tintas'!G51 -> 9 | I27: ='Muestras Tintas'!H51 -> 46098 | J27: ='Muestras Tintas'!I51 -> 3.16 | K27: ='Muestras Tintas'!J51 -> 23.1 | L27: ='Muestras Tintas'!L51*0.49 -> 4.8314 | M27: ='Muestras Tintas'!M51*1.53 -> 7.392042 | N27: ='Muestras Tintas'!O51/200 -> 1.38
A28: ='Muestras Tintas'!A52 -> CS26NILC2-H61/66-10 | B28: ='Muestras Tintas'!B52 -> Cabernet Sauvignon | C28: ='Muestras Tintas'!C52 -> Colchagua | D28: ='Muestras Tintas'!D52 -> NILAHUE | E28: ='Muestras Tintas'!E52 -> 2 | F28: ='Muestras Tintas'!F52 -> 61/66 | H28: ='Muestras Tintas'!G52 -> 10 | I28: ='Muestras Tintas'!H52 -> 46105 | J28: ='Muestras Tintas'!I52 -> 3.13 | K28: ='Muestras Tintas'!J52 -> 22.7 | L28: ='Muestras Tintas'!L52*0.49 -> 4.8853 | M28: ='Muestras Tintas'!M52*1.53 -> 7.474509 | N28: ='Muestras Tintas'!O52/200 -> 1.405
A29: ='Muestras Tintas'!A53 -> CS26NILC2-H61/66-11 | B29: ='Muestras Tintas'!B53 -> Cabernet Sauvignon | C29: ='Muestras Tintas'!C53 -> Colchagua | D29: ='Muestras Tintas'!D53 -> NILAHUE | E29: ='Muestras Tintas'!E53 -> 2 | F29: ='Muestras Tintas'!F53 -> 61/66 | H29: ='Muestras Tintas'!G53 -> 11 | I29: ='Muestras Tintas'!H53 -> 46112 | J29: ='Muestras Tintas'!I53 -> 3.21 | K29: ='Muestras Tintas'!J53 -> 25.7 | L29: ='Muestras Tintas'!L53*0.49 -> 5.0764 | M29: ='Muestras Tintas'!M53*1.53 -> 7.766892 | N29: ='Muestras Tintas'!O53/200 -> 1.315
A30: ='Muestras Tintas'!A54 -> CS26NILC2-H61/66-12 | B30: ='Muestras Tintas'!B54 -> Cabernet Sauvignon | C30: ='Muestras Tintas'!C54 -> Colchagua | D30: ='Muestras Tintas'!D54 -> NILAHUE | E30: ='Muestras Tintas'!E54 -> 2 | F30: ='Muestras Tintas'!F54 -> 61/66 | H30: ='Muestras Tintas'!G54 -> 12 | I30: ='Muestras Tintas'!H54 -> 46119 | J30: ='Muestras Tintas'!I54 -> 3.26 | K30: ='Muestras Tintas'!J54 -> 25.2 | L30: ='Muestras Tintas'!L54*0.49 -> 4.2777 | M30: ='Muestras Tintas'!M54*1.53 -> 6.544881 | N30: ='Muestras Tintas'!O54/200 -> 1.25
A31: ='Muestras Tintas'!A55 -> CS26NILC2-H61/66-13 | B31: ='Muestras Tintas'!B55 -> Cabernet Sauvignon | C31: ='Muestras Tintas'!C55 -> Colchagua | D31: ='Muestras Tintas'!D55 -> NILAHUE | E31: ='Muestras Tintas'!E55 -> 2 | F31: ='Muestras Tintas'!F55 -> 61/66 | H31: ='Muestras Tintas'!G55 -> 13 | I31: ='Muestras Tintas'!H55 -> 46126 | J31: ='Muestras Tintas'!I55 -> 3.22 | K31: ='Muestras Tintas'!J55 -> 25 | L31: ='Muestras Tintas'!L55*0.49 -> 5.0323 | M31: ='Muestras Tintas'!M55*1.53 -> 7.699419 | N31: ='Muestras Tintas'!O55/200 -> 1.301

Sheet CA-Peumo
A2: 2025
A3: Id. original muestra | B3: Variedad | C3: Valle | D3: Fundo | E3: Cuartel | F3: Hilera | G3: Muestreo Fenoles | H3: Muestreo | I3: Fecha | J3: pH | K3: Brix | L3: Acidez Sulfúrica | M3: Acidez Tartárica | N3: Peso Baya
A4: CA25PEUC93-H269/271-1 | B4: Carmenere | C4: ='Muestras Tintas'!C39 -> Colchagua | D4: PEUMO | E4: 93 | F4: 269/271 | H4: 1 | I4: 45698 | J4: 3.14 | K4: 19.4 | L4: 5.0862 | M4: 7.7819 | N4: 1.88
A5: CA25PEUC93-H269/271-2 | B5: Carmenere | C5: ='Muestras Tintas'!C40 -> Colchagua | D5: PEUMO | E5: 93 | F5: 269/271 | H5: 2 | I5: 45705 | J5: 3.22 | K5: 20.2 | L5: 4.9098 | M5: 7.512 | N5: 1.86
A6: CA25PEUC93-H269/271-3 | B6: Carmenere | C6: ='Muestras Tintas'!C43 -> Colchagua | D6: PEUMO | E6: 93 | F6: 269/271 | H6: 3 | I6: 45712 | J6: 3.29 | K6: 21.5 | L6: 4.2924 | M6: 6.5674 | N6: 1.9
A7: CA25PEUC93-H269/271-4 | B7: Carmenere | C7: ='Muestras Tintas'!C44 -> Colchagua | D7: PEUMO | E7: 93 | F7: 269/271 | H7: 4 | I7: 45719 | J7: 3.41 | K7: 22 | L7: 3.8808 | M7: 5.9376 | N7: 2.1
A8: CA25PEUC93-H269/271-5 | B8: Carmenere | C8: ='Muestras Tintas'!C45 -> Colchagua | D8: PEUMO | E8: 93 | F8: 269/271 | H8: 5 | I8: 45726 | J8: 3.54 | K8: 22.2 | L8: 3.4692 | M8: 5.3079 | N8: 2.32
A9: CA25PEUC93-H269/271-6 | B9: Carmenere | C9: ='Muestras Tintas'!C46 -> Colchagua | D9: PEUMO | E9: 93 | F9: 269/271 | G9: 45733 | H9: 6 | I9: 45733 | J9: 3.55 | K9: 22.4 | L9: 3.4447 | M9: 5.2704 | N9: 1.98
A10: CA25PEUC93-H269/271-7 | B10: Carmenere | C10: ='Muestras Tintas'!C47 -> Colchagua | D10: PEUMO | E10: 93 | F10: 269/271 | G10: 45740 | H10: 7 | I10: 45740 | J10: 3.66 | K10: 23.2 | L10: 3.2095 | M10: 4.9105 | N10: 2.09
A11: CA25PEUC93-H269/271-8 | B11: Carmenere | C11: ='Muestras Tintas'!C48 -> Colchagua | D11: PEUMO | E11: 93 | F11: 269/271 | G11: 45750 | H11: 8 | I11: 45750 | J11: 3.75 | K11: 23.8 | L11: 2.7391 | M11: 4.1908 | N11: 2.45
A12: CA25PEUC93-H269/271-9 | B12: Carmenere | C12: ='Muestras Tintas'!C49 -> Colchagua | D12: PEUMO | E12: 93 | F12: 269/271 | G12: 45764 | H12: 9 | I12: 45764 | J12: 3.92 | K12: 23.9 | L12: 2.499 | M12: 3.8235 | N12: 1.87
A13: CA25PEUC93-H269/271-10 | B13: Carmenere | C13: ='Muestras Tintas'!C50 -> Colchagua | D13: PEUMO | E13: 93 | F13: 269/271 | G13: 45777 | H13: 10 | I13: 45777 | J13: 4.12 | K13: 25.3 | L13: 2.1952 | M13: 3.3587 | N13: 2.05
A14: CA25PEUC93-H269/271-11 | B14: Carmenere | C14: ='Muestras Tintas'!C51 -> Colchagua | D14: PEUMO | E14: 93 | F14: 269/271 | G14: 45783 | H14: 11 | I14: 45783 | J14: 3.74 | K14: 24.5 | L14: 2.3716 | M14: 3.6285 | N14: 2.49
A16: 2026
A17: Id. original muestra | B17: Variedad | C17: Valle | D17: Fundo | E17: Cuartel | F17: Hilera | G17: Muestreo Fenoles | H17: Muestreo | I17: Fecha | J17: pH | K17: Brix | L17: Acidez Sulfúrica | M17: Acidez Tartárica | N17: Peso Baya | O17: COSECHA
A18: ='Muestras Tintas'!A56 -> CA26PEUC93-H267/271-1 | B18: ='Muestras Tintas'!B56 -> Carmenere | C18: ='Muestras Tintas'!C56 -> Cachapoal | D18: ='Muestras Tintas'!D56 -> PEUMO | E18: ='Muestras Tintas'!E56 -> 93 | F18: ='Muestras Tintas'!F56 -> 267/271 | H18: ='Muestras Tintas'!G56 -> 1 | I18: ='Muestras Tintas'!H56 -> 46044 | J18: ='Muestras Tintas'!I56 -> 2.98 | K18: ='Muestras Tintas'!J56 -> 15.1 | L18: ='Muestras Tintas'!L56*0.49 -> 8.477 | M18: ='Muestras Tintas'!M56*1.53 -> 12.96981 | N18: ='Muestras Tintas'!O56/200 -> 1.50375
A19: ='Muestras Tintas'!A57 -> CA26PEUC93-H267/271-2 | B19: ='Muestras Tintas'!B57 -> Carmenere | C19: ='Muestras Tintas'!C57 -> Cachapoal | D19: ='Muestras Tintas'!D57 -> PEUMO | E19: ='Muestras Tintas'!E57 -> 93 | F19: ='Muestras Tintas'!F57 -> 267/271 | H19: ='Muestras Tintas'!G57 -> 2 | I19: ='Muestras Tintas'!H57 -> 46050 | J19: ='Muestras Tintas'!I57 -> 3.07 | K19: ='Muestras Tintas'!J57 -> 16.2 | L19: ='Muestras Tintas'!L57*0.49 -> 7.5264 | M19: ='Muestras Tintas'!M57*1.53 -> 11.515392 | N19: ='Muestras Tintas'!O57/200 -> 1.563
A20: ='Muestras Tintas'!A58 -> CA26PEUC93-H267/271-3 | B20: ='Muestras Tintas'!B58 -> Carmenere | C20: ='Muestras Tintas'!C58 -> Cachapoal | D20: ='Muestras Tintas'!D58 -> PEUMO | E20: ='Muestras Tintas'!E58 -> 93 | F20: ='Muestras Tintas'!F58 -> 267/271 | H20: ='Muestras Tintas'!G58 -> 3 | I20: ='Muestras Tintas'!H58 -> 46057 | J20: ='Muestras Tintas'!I58 -> 3.18 | K20: ='Muestras Tintas'!J58 -> 18.4 | L20: ='Muestras Tintas'!L58*0.49 -> 5.292 | M20: ='Muestras Tintas'!M58*1.53 -> 8.09676 | N20: ='Muestras Tintas'!O58/200 -> 1.7135
A21: ='Muestras Tintas'!A59 -> CA26PEUC93-H267/271-4 | B21: ='Muestras Tintas'!B59 -> Carmenere | C21: ='Muestras Tintas'!C59 -> Cachapoal | D21: ='Muestras Tintas'!D59 -> PEUMO | E21: ='Muestras Tintas'!E59 -> 93 | F21: ='Muestras Tintas'!F59 -> 267/271 | H21: ='Muestras Tintas'!G59 -> 4 | I21: ='Muestras Tintas'!H59 -> 46064 | J21: ='Muestras Tintas'!I59 -> 3.33 | K21: ='Muestras Tintas'!J59 -> 19.3 | L21: ='Muestras Tintas'!L59*0.49 -> 4.5962 | M21: ='Muestras Tintas'!M59*1.53 -> 7.032186 | N21: ='Muestras Tintas'!O59/200 -> 2.0165
A22: ='Muestras Tintas'!A60 -> CA26PEUC93-H267/271-5 | B22: ='Muestras Tintas'!B60 -> Carmenere | C22: ='Muestras Tintas'!C60 -> Cachapoal | D22: ='Muestras Tintas'!D60 -> PEUMO | E22: ='Muestras Tintas'!E60 -> 93 | F22: ='Muestras Tintas'!F60 -> 267/271 | H22: ='Muestras Tintas'!G60 -> 5 | I22: ='Muestras Tintas'!H60 -> 46071 | J22: ='Muestras Tintas'!I60 -> 3.45 | K22: ='Muestras Tintas'!J60 -> 20.6 | L22: ='Muestras Tintas'!L60*0.49 -> 3.7044 | M22: ='Muestras Tintas'!M60*1.53 -> 5.667732 | N22: ='Muestras Tintas'!O60/200 -> 1.934
A23: ='Muestras Tintas'!A61 -> CA26PEUC93-H267/271-6 | B23: ='Muestras Tintas'!B61 -> Carmenere | C23: ='Muestras Tintas'!C61 -> Cachapoal | D23: ='Muestras Tintas'!D61 -> PEUMO | E23: ='Muestras Tintas'!E61 -> 93 | F23: ='Muestras Tintas'!F61 -> 267/271 | H23: ='Muestras Tintas'!G61 -> 6 | I23: ='Muestras Tintas'!H61 -> 46078 | J23: ='Muestras Tintas'!I61 -> 3.47 | K23: ='Muestras Tintas'!J61 -> 21.2 | L23: ='Muestras Tintas'!L61*0.49 -> 3.3516 | M23: ='Muestras Tintas'!M61*1.53 -> 5.127948 | N23: ='Muestras Tintas'!O61/200 -> 1.7935
A24: ='Muestras Tintas'!A62 -> CA26PEUC93-H267/271-7 | B24: ='Muestras Tintas'!B62 -> Carmenere | C24: ='Muestras Tintas'!C62 -> Cachapoal | D24: ='Muestras Tintas'!D62 -> PEUMO | E24: ='Muestras Tintas'!E62 -> 93 | F24: ='Muestras Tintas'!F62 -> 267/271 | H24: ='Muestras Tintas'!G62 -> 7 | I24: ='Muestras Tintas'!H62 -> 46085 | J24: ='Muestras Tintas'!I62 -> 3.59 | K24: ='Muestras Tintas'!J62 -> 22.1 | L24: ='Muestras Tintas'!L62*0.49 -> 2.7881 | M24: ='Muestras Tintas'!M62*1.53 -> 4.265793 | N24: ='Muestras Tintas'!O62/200 -> 1.986
A25: ='Muestras Tintas'!A63 -> CA26PEUC93-H267/271-8 | B25: ='Muestras Tintas'!B63 -> Carmenere | C25: ='Muestras Tintas'!C63 -> Cachapoal | D25: ='Muestras Tintas'!D63 -> PEUMO | E25: ='Muestras Tintas'!E63 -> 93 | F25: ='Muestras Tintas'!F63 -> 267/271 | H25: ='Muestras Tintas'!G63 -> 8 | I25: ='Muestras Tintas'!H63 -> 46092 | J25: ='Muestras Tintas'!I63 -> 3.63 | K25: ='Muestras Tintas'!J63 -> 22.2 | L25: ='Muestras Tintas'!L63*0.49 -> 2.6999 | M25: ='Muestras Tintas'!M63*1.53 -> 4.130847 | N25: ='Muestras Tintas'!O63/200 -> 1.827
A26: ='Muestras Tintas'!A64 -> CA26PEUC93-H267/271-9 | B26: ='Muestras Tintas'!B64 -> Carmenere | C26: ='Muestras Tintas'!C64 -> Cachapoal | D26: ='Muestras Tintas'!D64 -> PEUMO | E26: ='Muestras Tintas'!E64 -> 93 | F26: ='Muestras Tintas'!F64 -> 267/271 | H26: ='Muestras Tintas'!G64 -> 9 | I26: ='Muestras Tintas'!H64 -> 46099 | J26: ='Muestras Tintas'!I64 -> 3.61 | K26: ='Muestras Tintas'!J64 -> 22.5 | L26: ='Muestras Tintas'!L64*0.49 -> 2.6509 | M26: ='Muestras Tintas'!M64*1.53 -> 4.055877 | N26: ='Muestras Tintas'!O64/200 -> 1.718
A27: ='Muestras Tintas'!A65 -> CA26PEUC93-H267/271-10 | B27: ='Muestras Tintas'!B65 -> Carmenere | C27: ='Muestras Tintas'!C65 -> Cachapoal | D27: ='Muestras Tintas'!D65 -> PEUMO | E27: ='Muestras Tintas'!E65 -> 93 | F27: ='Muestras Tintas'!F65 -> 267/271 | H27: ='Muestras Tintas'!G65 -> 10 | I27: ='Muestras Tintas'!H65 -> 46107 | J27: ='Muestras Tintas'!I65 -> 3.6 | K27: ='Muestras Tintas'!J65 -> 23.8 | L27: ='Muestras Tintas'!L65*0.49 -> 2.254 | M27: ='Muestras Tintas'!M65*1.53 -> 3.44862 | N27: ='Muestras Tintas'!O65/200 -> 1.843
A28: ='Muestras Tintas'!A66 -> CA26PEUC93-H267/271-11 | B28: ='Muestras Tintas'!B66 -> Carmenere | C28: ='Muestras Tintas'!C66 -> Cachapoal | D28: ='Muestras Tintas'!D66 -> PEUMO | E28: ='Muestras Tintas'!E66 -> 93 | F28: ='Muestras Tintas'!F66 -> 267/271 | H28: ='Muestras Tintas'!G66 -> 11 | I28: ='Muestras Tintas'!H66 -> 46113 | J28: ='Muestras Tintas'!I66 -> 3.75 | K28: ='Muestras Tintas'!J66 -> 23.8 | L28: ='Muestras Tintas'!L66*0.49 -> 2.1119 | M28: ='Muestras Tintas'!M66*1.53 -> 3.231207 | N28: ='Muestras Tintas'!O66/200 -> 2.071
A29: ='Muestras Tintas'!A67 -> CA26PEUC93-H267/271-12 | B29: ='Muestras Tintas'!B67 -> Carmenere | C29: ='Muestras Tintas'!C67 -> Cachapoal | D29: ='Muestras Tintas'!D67 -> PEUMO | E29: ='Muestras Tintas'!E67 -> 93 | F29: ='Muestras Tintas'!F67 -> 267/271 | H29: ='Muestras Tintas'!G67 -> 12 | I29: ='Muestras Tintas'!H67 -> 46120 | J29: ='Muestras Tintas'!I67 -> 3.64 | K29: ='Muestras Tintas'!J67 -> 23.8 | L29: ='Muestras Tintas'!L67*0.49 -> 2.8126 | M29: ='Muestras Tintas'!M67*1.53 -> 4.303278 | N29: ='Muestras Tintas'!O67/200 -> 1.6865
A30: ='Muestras Tintas'!A68 -> CA26PEUC93-H267/271-13 | B30: ='Muestras Tintas'!B68 -> Carmenere | C30: ='Muestras Tintas'!C68 -> Cachapoal | D30: ='Muestras Tintas'!D68 -> PEUMO | E30: ='Muestras Tintas'!E68 -> 93 | F30: ='Muestras Tintas'!F68 -> 267/271 | H30: ='Muestras Tintas'!G68 -> 13 | I30: ='Muestras Tintas'!H68 -> 46127 | J30: ='Muestras Tintas'!I68 -> 3.34 | K30: ='Muestras Tintas'!J68 -> 22.8 | L30: ='Muestras Tintas'!L68*0.49 -> 4.0082 | M30: ='Muestras Tintas'!M68*1.53 -> 6.132546 | O30: 4
A31: ='Muestras Tintas'!A69 -> CA26PEUC93-H267/271-14 | B31: ='Muestras Tintas'!B69 -> Carmenere | C31: ='Muestras Tintas'!C69 -> Cachapoal | D31: ='Muestras Tintas'!D69 -> PEUMO | E31: ='Muestras Tintas'!E69 -> 93 | F31: ='Muestras Tintas'!F69 -> 267/271 | H31: ='Muestras Tintas'!G69 -> 14 | I31: ='Muestras Tintas'!H69 -> 46134 | J31: ='Muestras Tintas'!I69 -> 3.83 | K31: ='Muestras Tintas'!J69 -> 25.7 | L31: ='Muestras Tintas'!L69*0.49 -> 2.0776 | M31: ='Muestras Tintas'!M69*1.53 -> 3.178728 | N31: ='Muestras Tintas'!O69/200 -> 1.7705
A32: ='Muestras Tintas'!A70 -> CA26PEUC93-H267/271-15 | B32: ='Muestras Tintas'!B70 -> Carmenere | C32: ='Muestras Tintas'!C70 -> Cachapoal | D32: ='Muestras Tintas'!D70 -> PEUMO | E32: ='Muestras Tintas'!E70 -> 93 | F32: ='Muestras Tintas'!F70 -> 267/271 | H32: ='Muestras Tintas'!G70 -> 15 | I32: ='Muestras Tintas'!H70 -> 46141 | J32: ='Muestras Tintas'!I70 -> 3.32 | K32: ='Muestras Tintas'!J70 -> 23.3 | L32: ='Muestras Tintas'!L70*0.49 -> 4.0033 | M32: ='Muestras Tintas'!M70*1.53 -> 6.125049 | N32: ='Muestras Tintas'!O70/200 -> 1.3505 | O32: 5

Sheet CS-Keule
A2: 2025
A3: Id. original muestra | B3: Variedad | C3: Valle | D3: Fundo | E3: Cuartel | F3: Hilera | G3: Muestreo Fenoles | H3: Muestreo | I3: Fecha | J3: pH | K3: Brix | L3: Acidez Sulfúrica | M3: Acidez Tartárica | N3: Peso Baya
A4: CS25KEUC3-H1/7-1 | B4: Cabernet Sauvignon | C4: Maule | D4: KEULE | E4: 3 | F4: 1/7 | H4: 1 | I4: 45694 | J4: 2.73 | K4: 17.8 | L4: 11.1132 | M4: 17.0032 | N4: 1.1
A5: CS25KEUC3-H1/7-2 | B5: Cabernet Sauvignon | C5: Maule | D5: KEULE | E5: 3 | F5: 1/7 | H5: 2 | I5: 45701 | J5: 2.77 | K5: 17.8 | L5: 9.9274 | M5: 15.1889 | N5: 1.04
A6: CS25KEUC3-H1/7-3 | B6: Cabernet Sauvignon | C6: Maule | D6: KEULE | E6: 3 | F6: 1/7 | H6: 3 | I6: 45708 | J6: 2.88 | K6: 19.5 | L6: 7.693 | M6: 11.7703 | N6: 1.22
A7: CS25KEUC3-H1/7-4 | B7: Cabernet Sauvignon | C7: Maule | D7: KEULE | E7: 3 | F7: 1/7 | G7: 45715 | H7: 4 | I7: 45715 | J7: 2.94 | K7: 20.9 | L7: 6.9874 | M7: 10.6907 | N7: 1.46
A8: CS25KEUC3-H1/7-5 | B8: Cabernet Sauvignon | C8: Maule | D8: KEULE | E8: 3 | F8: 1/7 | G8: 45726 | H8: 5 | I8: 45722 | J8: 3.17 | K8: 21.7 | L8: 6.0662 | M8: 9.2813 | N8: 1.53
A9: CS25KEUC3-H1/7-6 | B9: Cabernet Sauvignon | C9: Maule | D9: KEULE | E9: 3 | F9: 1/7 | G9: 45729 | H9: 6 | I9: 45729 | J9: 3.23 | K9: 23.1 | L9: 5.6399 | M9: 8.629 | N9: 1.65
A10: CS25KEUC3-H1/7-7 | B10: Cabernet Sauvignon | C10: Maule | D10: KEULE | E10: 3 | F10: 1/7 | G10: 45735 | H10: 7 | I10: 45735 | J10: 3.31 | K10: 23.4 | L10: 5.1548 | M10: 7.8868 | N10: 1.62
A11: CS25KEUC3-H1/7-8 | B11: Cabernet Sauvignon | C11: Maule | D11: KEULE | E11: 3 | F11: 1/7 | G11: 45742 | H11: 8 | I11: 45742 | J11: 3.33 | K11: 24 | L11: 4.7285 | M11: 7.2346 | N11: 1.58
A12: CS25KEUC3-H1/7-9 | B12: Cabernet Sauvignon | C12: Maule | D12: KEULE | E12: 3 | F12: 1/7 | G12: 45749 | H12: 9 | I12: 45749 | J12: 3.35 | K12: 24.9 | L12: 4.6991 | M12: 7.1896 | N12: 1.55
A13: CS25KEUC3-H1/7-10 | B13: Cabernet Sauvignon | C13: Maule | D13: KEULE | E13: 3 | F13: 1/7 | G13: 45757 | H13: 10 | I13: 45757 | J13: 3.29 | K13: 24.9 | L13: 4.6403 | M13: 7.0997 | N13: 1.59
A15: 2026
A16: Id. original muestra | B16: Variedad | C16: Valle | D16: Fundo | E16: Cuartel | F16: Hilera | G16: Muestreo Fenoles | H16: Muestreo | I16: Fecha | J16: pH | K16: Brix | L16: Acidez Sulfúrica | M16: Acidez Tartárica | N16: Peso Baya | O16: COSECHA
A17: ='Muestras Tintas'!A96 -> CS26KEUC3-H1/6-1 | B17: ='Muestras Tintas'!B96 -> Cabernet Sauvignon | C17: ='Muestras Tintas'!C96 -> Maule | D17: ='Muestras Tintas'!D96 -> KEULE | E17: ='Muestras Tintas'!E96 -> 3 | F17: ='Muestras Tintas'!F96 -> 1/6 | H17: ='Muestras Tintas'!G96 -> 1 | I17: ='Muestras Tintas'!H96 -> 46044 | J17: ='Muestras Tintas'!I96 -> 2.84 | K17: ='Muestras Tintas'!J96 -> 15.2 | L17: ='Muestras Tintas'!L96*0.49 -> 14.4354 | M17: ='Muestras Tintas'!M96*1.53 -> 22.086162 | N17: ='Muestras Tintas'!O96/200 -> 1.0749
A18: ='Muestras Tintas'!A97 -> CS26KEUC3-H1/6-2 | B18: ='Muestras Tintas'!B97 -> Cabernet Sauvignon | C18: ='Muestras Tintas'!C97 -> Maule | D18: ='Muestras Tintas'!D97 -> KEULE | E18: ='Muestras Tintas'!E97 -> 3 | F18: ='Muestras Tintas'!F97 -> 1/6 | H18: ='Muestras Tintas'!G97 -> 2 | I18: ='Muestras Tintas'!H97 -> 46051 | J18: ='Muestras Tintas'!I97 -> 2.87 | K18: ='Muestras Tintas'!J97 -> 16 | L18: ='Muestras Tintas'!L97*0.49 -> 11.858 | M18: ='Muestras Tintas'!M97*1.53 -> 18.14274 | N18: ='Muestras Tintas'!O97/200 -> 1.16885
A19: ='Muestras Tintas'!A98 -> CS26KEUC3-H1/6-3 | B19: ='Muestras Tintas'!B98 -> Cabernet Sauvignon | C19: ='Muestras Tintas'!C98 -> Maule | D19: ='Muestras Tintas'!D98 -> KEULE | E19: ='Muestras Tintas'!E98 -> 3 | F19: ='Muestras Tintas'!F98 -> 1/6 | H19: ='Muestras Tintas'!G98 -> 3 | I19: ='Muestras Tintas'!H98 -> 46057 | J19: ='Muestras Tintas'!I98 -> 2.97 | K19: ='Muestras Tintas'!J98 -> 17.2 | L19: ='Muestras Tintas'!L98*0.49 -> 9.849 | M19: ='Muestras Tintas'!M98*1.53 -> 15.06897 | N19: ='Muestras Tintas'!O98/200 -> 1.2685
A20: ='Muestras Tintas'!A99 -> CS26KEUC3-H1/6-4 | B20: ='Muestras Tintas'!B99 -> Cabernet Sauvignon | C20: ='Muestras Tintas'!C99 -> Maule | D20: ='Muestras Tintas'!D99 -> KEULE | E20: ='Muestras Tintas'!E99 -> 3 | F20: ='Muestras Tintas'!F99 -> 1/6 | H20: ='Muestras Tintas'!G99 -> 4 | I20: ='Muestras Tintas'!H99 -> 46064 | J20: ='Muestras Tintas'!I99 -> 3.03 | K20: ='Muestras Tintas'!J99 -> 18.7 | L20: ='Muestras Tintas'!L99*0.49 -> 8.5946 | M20: ='Muestras Tintas'!M99*1.53 -> 13.149738 | N20: ='Muestras Tintas'!O99/200 -> 1.2415
A21: ='Muestras Tintas'!A100 -> CS26KEUC3-H1/6-5 | B21: ='Muestras Tintas'!B100 -> Cabernet Sauvignon | C21: ='Muestras Tintas'!C100 -> Maule | D21: ='Muestras Tintas'!D100 -> KEULE | E21: ='Muestras Tintas'!E100 -> 3 | F21: ='Muestras Tintas'!F100 -> 1/6 | H21: ='Muestras Tintas'!G100 -> 5 | I21: ='Muestras Tintas'!H100 -> 46072 | J21: ='Muestras Tintas'!I100 -> 3.11 | K21: ='Muestras Tintas'!J100 -> 21.1 | L21: ='Muestras Tintas'!L100*0.49 -> 6.6444 | M21: ='Muestras Tintas'!M100*1.53 -> 10.165932 | N21: ='Muestras Tintas'!O100/200 -> 1.548
A22: ='Muestras Tintas'!A101 -> CS26KEUC3-H1/6-6 | B22: ='Muestras Tintas'!B101 -> Cabernet Sauvignon | C22: ='Muestras Tintas'!C101 -> Maule | D22: ='Muestras Tintas'!D101 -> KEULE | E22: ='Muestras Tintas'!E101 -> 3 | F22: ='Muestras Tintas'!F101 -> 1/6 | H22: ='Muestras Tintas'!G101 -> 6 | I22: ='Muestras Tintas'!H101 -> 46078 | J22: ='Muestras Tintas'!I101 -> 3.09 | K22: ='Muestras Tintas'!J101 -> 22.5 | L22: ='Muestras Tintas'!L101*0.49 -> 6.0858 | M22: ='Muestras Tintas'!M101*1.53 -> 9.311274 | N22: ='Muestras Tintas'!O101/200 -> 1.292
A23: ='Muestras Tintas'!A102 -> CS26KEUC3-H1/6-7 | B23: ='Muestras Tintas'!B102 -> Cabernet Sauvignon | C23: ='Muestras Tintas'!C102 -> Maule | D23: ='Muestras Tintas'!D102 -> KEULE | E23: ='Muestras Tintas'!E102 -> 3 | F23: ='Muestras Tintas'!F102 -> 1/6 | H23: ='Muestras Tintas'!G102 -> 7 | I23: ='Muestras Tintas'!H102 -> 46087 | J23: ='Muestras Tintas'!I102 -> 3.15 | K23: ='Muestras Tintas'!J102 -> 22.8 | L23: ='Muestras Tintas'!L102*0.49 -> 6.0564 | M23: ='Muestras Tintas'!M102*1.53 -> 9.266292 | N23: ='Muestras Tintas'!O102/200 -> 1.5155 | O23: 1
A24: ='Muestras Tintas'!A103 -> CS26KEUC3-H1/6-8 | B24: ='Muestras Tintas'!B103 -> Cabernet Sauvignon | C24: ='Muestras Tintas'!C103 -> Maule | D24: ='Muestras Tintas'!D103 -> KEULE | E24: ='Muestras Tintas'!E103 -> 3 | F24: ='Muestras Tintas'!F103 -> 1/6 | H24: ='Muestras Tintas'!G103 -> 8 | I24: ='Muestras Tintas'!H103 -> 46092 | J24: ='Muestras Tintas'!I103 -> 3.21 | K24: ='Muestras Tintas'!J103 -> 23.5 | L24: ='Muestras Tintas'!L103*0.49 -> 6.0025 | M24: ='Muestras Tintas'!M103*1.53 -> 9.183825 | N24: ='Muestras Tintas'!O103/200 -> 1.307
A25: ='Muestras Tintas'!A104 -> CS26KEUC3-H1/6-9 | B25: ='Muestras Tintas'!B104 -> Cabernet Sauvignon | C25: ='Muestras Tintas'!C104 -> Maule | D25: ='Muestras Tintas'!D104 -> KEULE | E25: ='Muestras Tintas'!E104 -> 3 | F25: ='Muestras Tintas'!F104 -> 1/6 | H25: ='Muestras Tintas'!G104 -> 9 | I25: ='Muestras Tintas'!H104 -> 46100 | J25: ='Muestras Tintas'!I104 -> 3.21 | K25: ='Muestras Tintas'!J104 -> 24.4 | L25: ='Muestras Tintas'!L104*0.49 -> 4.7775 | M25: ='Muestras Tintas'!M104*1.53 -> 7.309575 | N25: ='Muestras Tintas'!O104/200 -> 1.3455 | O25: 2
A26: ='Muestras Tintas'!A105 -> CS26KEUC3-H1/6-10 | B26: ='Muestras Tintas'!B105 -> Cabernet Sauvignon | C26: ='Muestras Tintas'!C105 -> Maule | D26: ='Muestras Tintas'!D105 -> KEULE | E26: ='Muestras Tintas'!E105 -> 3 | F26: ='Muestras Tintas'!F105 -> 1/6 | H26: ='Muestras Tintas'!G105 -> 10 | I26: ='Muestras Tintas'!H105 -> 46108 | J26: ='Muestras Tintas'!I105 -> 3.64 | K26: ='Muestras Tintas'!J105 -> 25.4 | L26: ='Muestras Tintas'!L105*0.49 -> 2.5431 | M26: ='Muestras Tintas'!M105*1.53 -> 3.890943 | N26: ='Muestras Tintas'!O105/200 -> 1.6365
A27: ='Muestras Tintas'!A106 -> CS26KEUC3-H1/6-11 | B27: ='Muestras Tintas'!B106 -> Cabernet Sauvignon | C27: ='Muestras Tintas'!C106 -> Maule | D27: ='Muestras Tintas'!D106 -> KEULE | E27: ='Muestras Tintas'!E106 -> 3 | F27: ='Muestras Tintas'!F106 -> 1/6 | H27: ='Muestras Tintas'!G106 -> 11 | I27: ='Muestras Tintas'!H106 -> 46113 | J27: ='Muestras Tintas'!I106 -> 3.16 | K27: ='Muestras Tintas'!J106 -> 24.8 | L27: ='Muestras Tintas'!L106*0.49 -> 4.2532 | M27: ='Muestras Tintas'!M106*1.53 -> 6.507396 | N27: ='Muestras Tintas'!O106/200 -> 1.267
A28: ='Muestras Tintas'!A107 -> CS26KEUC3-H1/6-12 | B28: ='Muestras Tintas'!B107 -> Cabernet Sauvignon | C28: ='Muestras Tintas'!C107 -> Maule | D28: ='Muestras Tintas'!D107 -> KEULE | E28: ='Muestras Tintas'!E107 -> 3 | F28: ='Muestras Tintas'!F107 -> 1/6 | H28: ='Muestras Tintas'!G107 -> 12 | I28: ='Muestras Tintas'!H107 -> 46120 | J28: ='Muestras Tintas'!I107 -> 3.26 | K28: ='Muestras Tintas'!J107 -> 25.6 | L28: ='Muestras Tintas'!L107*0.49 -> 4.1699 | M28: ='Muestras Tintas'!M107*1.53 -> 6.379947 | N28: ='Muestras Tintas'!O107/200 -> 1.499
A29: ='Muestras Tintas'!A108 -> CS26KEUC3-H1/6-13 | B29: ='Muestras Tintas'!B108 -> Cabernet Sauvignon | C29: ='Muestras Tintas'!C108 -> Maule | D29: ='Muestras Tintas'!D108 -> KEULE | E29: ='Muestras Tintas'!E108 -> 3 | F29: ='Muestras Tintas'!F108 -> 1/6 | H29: ='Muestras Tintas'!G108 -> 13 | I29: ='Muestras Tintas'!H108 -> 46128 | J29: ='Muestras Tintas'!I108 -> 3.34 | K29: ='Muestras Tintas'!J108 -> 26.6 | L29: ='Muestras Tintas'!L108*0.49 -> 4.116 | M29: ='Muestras Tintas'!M108*1.53 -> 6.29748 | N29: ='Muestras Tintas'!O108/200 -> 1.39

Sheet CA-Villa_Alegre
A2: 2025
A3: Id. original muestra | B3: Variedad | C3: Valle | D3: Fundo | E3: Cuartel | F3: Hilera | G3: Muestreo Fenoles | H3: Muestreo | I3: Fecha | J3: pH | K3: Brix | L3: Acidez Sulfúrica | M3: Acidez Tartárica | N3: Peso Baya
A4: CA25VALC13-H1/15-1 | B4: Carmenere | C4: ='Muestras Tintas'!C96 -> Maule | D4: VILLA ALEGRE | E4: 13 | F4: 1/15 | H4: 1 | I4: 45708 | J4: 3.19 | K4: 21.7 | L4: 3.3908 | M4: 5.1879 | N4: 1.81
A5: CA25VALC13-H1/15-2 | B5: Carmenere | C5: ='Muestras Tintas'!C97 -> Maule | D5: VILLA ALEGRE | E5: 13 | F5: 1/15 | G5: 45715 | H5: 2 | I5: 45715 | J5: 3.2 | K5: 23 | L5: 3.5084 | M5: 5.3679 | N5: 1.88
A6: CA25VALC13-H1/15-3 | B6: Carmenere | C6: ='Muestras Tintas'!C98 -> Maule | D6: VILLA ALEGRE | E6: 13 | F6: 1/15 | G6: 45726 | H6: 3 | I6: 45722 | J6: 3.43 | K6: 23.9 | L6: 2.793 | M6: 4.2733 | N6: 2.23
A7: CA25VALC13-H1/15-4 | B7: Carmenere | C7: ='Muestras Tintas'!C99 -> Maule | D7: VILLA ALEGRE | E7: 13 | F7: 1/15 | G7: 45729 | H7: 4 | I7: 45729 | J7: 3.5 | K7: 25.1 | L7: 2.7146 | M7: 4.1533 | N7: 2.26
A8: CA25VALC13-H1/15-5 | B8: Carmenere | C8: ='Muestras Tintas'!C100 -> Maule | D8: VILLA ALEGRE | E8: 13 | F8: 1/15 | G8: 45736 | H8: 5 | I8: 45736 | J8: 3.62 | K8: 25.6 | L8: 2.6705 | M8: 4.0859 | N8: 2.23
A9: CA25VALC13-H1/15-6 | B9: Carmenere | C9: ='Muestras Tintas'!C101 -> Maule | D9: VILLA ALEGRE | E9: 13 | F9: 1/15 | G9: 45743 | H9: 6 | I9: 45743 | J9: 3.63 | K9: 26.2 | L9: 2.3912 | M9: 3.6585 | N9: 2.31
A10: CA25VALC13-H1/15-7 | B10: Carmenere | C10: ='Muestras Tintas'!C102 -> Maule | D10: VILLA ALEGRE | E10: 13 | F10: 1/15 | G10: 45750 | H10: 7 | I10: 45750 | J10: 3.83 | K10: 24.4 | L10: 1.9404 | M10: 2.9688 | N10: 2.08
A12: 2026
A13: Id. original muestra | B13: Variedad | C13: Valle | D13: Fundo | E13: Cuartel | F13: Hilera | G13: Muestreo Fenoles | H13: Muestreo | I13: Fecha | J13: pH | K13: Brix | L13: Acidez Sulfúrica | M13: Acidez Tartárica | N13: Peso Baya | O13: COSECHA
A14: ='Muestras Tintas'!A109 -> CA26VALC13-H1/13-1 | B14: ='Muestras Tintas'!B109 -> Carmenere | C14: ='Muestras Tintas'!C109 -> Maule | D14: ='Muestras Tintas'!D109 -> VILLA ALEGRE | E14: ='Muestras Tintas'!E109 -> 13 | F14: ='Muestras Tintas'!F109 -> 1/13 | H14: ='Muestras Tintas'!G109 -> 1 | I14: ='Muestras Tintas'!H109 -> 46045 | J14: ='Muestras Tintas'!I109 -> 3.04 | K14: ='Muestras Tintas'!J109 -> 15.1 | L14: ='Muestras Tintas'!L109*0.49 -> 6.5758 | M14: ='Muestras Tintas'!M109*1.53 -> 10.060974 | N14: ='Muestras Tintas'!O109/200 -> 1.47255
A15: ='Muestras Tintas'!A110 -> CA26VALC13-H1/13-2 | B15: ='Muestras Tintas'!B110 -> Carmenere | C15: ='Muestras Tintas'!C110 -> Maule | D15: ='Muestras Tintas'!D110 -> VILLA ALEGRE | E15: ='Muestras Tintas'!E110 -> 13 | F15: ='Muestras Tintas'!F110 -> 1/13 | H15: ='Muestras Tintas'!G110 -> 2 | I15: ='Muestras Tintas'!H110 -> 46051 | J15: ='Muestras Tintas'!I110 -> 3.08 | K15: ='Muestras Tintas'!J110 -> 16.9 | L15: ='Muestras Tintas'!L110*0.49 -> 5.1842 | M15: ='Muestras Tintas'!M110*1.53 -> 7.931826 | N15: ='Muestras Tintas'!O110/200 -> 1.5821
A16: ='Muestras Tintas'!A111 -> CA26VALC13-H1/13-3 | B16: ='Muestras Tintas'!B111 -> Carmenere | C16: ='Muestras Tintas'!C111 -> Maule | D16: ='Muestras Tintas'!D111 -> VILLA ALEGRE | E16: ='Muestras Tintas'!E111 -> 13 | F16: ='Muestras Tintas'!F111 -> 1/13 | H16: ='Muestras Tintas'!G111 -> 3 | I16: ='Muestras Tintas'!H111 -> 46058 | J16: ='Muestras Tintas'!I111 -> 3.2 | K16: ='Muestras Tintas'!J111 -> 18.2 | L16: ='Muestras Tintas'!L111*0.49 -> 3.9053 | M16: ='Muestras Tintas'!M111*1.53 -> 5.975109 | N16: ='Muestras Tintas'!O111/200 -> 1.793
