Workbook

Sheet Tabla general
A1: Id. original muestra | B1: Variedad | C1: Valles | D1: Fundo | E1: Cuartel | F1: Hilera | G1: N° muestra | H1: Fecha | I1: pH | J1: Brix | K1: NaOH | L1: Acidez Sulfúrica | M1: Acidez Tartárica | N1: Peso muestra | O1: N° bayas | P1: Peso baya
A2: CH26IDAC1-H135-1 | B2: Chardonnay | C2: Colchagua | D2: IDAHUE | E2: 1 | F2: 135 | G2: =_xlfn.TEXTAFTER(A2, "-", 2) -> 1 | H2: 46035 | I2: 2.81 | J2: 9.7 | K2: 37.34 | L2: =K2*0.49 -> 18.2966 | M2: =L2*1.53 -> 27.993798 | N2: 192.45 | O2: 200 | P2: =N2/O2 -> 0.96225
A3: CH26IDAC1-H135-2 | B3: Chardonnay | C3: Colchagua | D3: IDAHUE | E3: 1 | F3: 135 | G3: =_xlfn.TEXTAFTER(A3, "-", 2) -> 2 | H3: 46044 | I3: 2.85 | J3: 12.6 | K3: 13.83 | L3: =K3*0.49 -> 6.7767 | M3: =L3*1.53 -> 10.368351 | N3: 188.96 | O3: 200 | P3: =N3/O3 -> 0.9448 | T3: Fundo | U3: Cuartel | V3: Variedad | W3: Fecha cosecha
A4: CH26IDAC1-H135-3 | B4: Chardonnay | C4: Colchagua | D4: IDAHUE | E4: 1 | F4: 135 | G4: =_xlfn.TEXTAFTER(A4, "-", 2) -> 3 | H4: 46050 | I4: 2.97 | J4: 14.6 | K4: 19.04 | L4: =K4*0.49 -> 9.3296 | M4: =L4*1.53 -> 14.274288 | N4: 208.52 | O4: 200 | P4: =N4/O4 -> 1.0426 | T4: Lourdes | U4: 79 | V4: CH | W4: 46145
A5: CH26IDAC1-H135-4 | B5: Chardonnay | C5: Colchagua | D5: IDAHUE | E5: 1 | F5: 135 | G5: =_xlfn.TEXTAFTER(A5, "-", 2) -> 4 | H5: 46057 | I5: 3.01 | J5: 16 | K5: 16.18 | L5: =K5*0.49 -> 7.9282 | M5: =L5*1.53 -> 12.130146 | N5: 225.2 | O5: 200 | P5: =N5/O5 -> 1.126 | T5: Ucuquer | U5: 110 | V5: CH | W5: 46098
A6: CH26IDAC1-H135-5 | B6: Chardonnay | C6: Colchagua | D6: IDAHUE | E6: 1 | F6: 135 | G6: =_xlfn.TEXTAFTER(A6, "-", 2) -> 5 | H6: 46064 | I6: 3.12 | J6: 18 | K6: 14.04 | L6: =K6*0.49 -> 6.8796 | M6: =L6*1.53 -> 10.525788 | N6: 242.4 | O6: 200 | P6: =N6/O6 -> 1.212 | T6: Ucuquer | U6: 54 | V6: SB | W6: 46145
A7: CH26IDAC1-H135-6 | B7: Chardonnay | C7: Colchagua | D7: IDAHUE | E7: 1 | F7: 135 | G7: =_xlfn.TEXTAFTER(A7, "-", 2) -> 6 | H7: 46071 | I7: 3.18 | J7: 19.5 | K7: 12.8 | L7: =K7*0.49 -> 6.272 | M7: =L7*1.53 -> 9.59616 | N7: 230 | O7: 200 | P7: =N7/O7 -> 1.15 | T7: Yungay | U7: 4 | V7: SB
A8: CH26IDAC1-H135-7 | B8: Chardonnay | C8: Colchagua | D8: IDAHUE | E8: 1 | F8: 135 | G8: =_xlfn.TEXTAFTER(A8, "-", 2) -> 7 | H8: 46078 | I8: 3.2 | J8: 21.3 | K8: 10.32 | L8: =K8*0.49 -> 5.0568 | M8: =L8*1.53 -> 7.736904 | N8: 237.2 | O8: 200 | P8: =N8/O8 -> 1.186 | T8: Rauco | U8: 7 | V8: SB
A9: CH26IDAC1-H135-8 | B9: Chardonnay | C9: Colchagua | D9: IDAHUE | E9: 1 | F9: 135 | G9: =_xlfn.TEXTAFTER(A9, "-", 2) -> 8 | H9: 46085 | I9: 3.2 | J9: 21.7 | K9: 10.23 | L9: =K9*0.49 -> 5.0127 | M9: =L9*1.53 -> 7.669431 | N9: 232.5 | O9: 200 | P9: =N9/O9 -> 1.1625 | T9: Santa Isabel | U9: 27 | V9: SB | W9: 46091
A10: CH26IDAC1-H135-9 | B10: Chardonnay | C10: Colchagua | D10: IDAHUE | E10: 1 | F10: 135 | G10: =_xlfn.TEXTAFTER(A10, "-", 2) -> 9 | H10: 46092 | I10: 3.27 | J10: 22.8 | K10: 9.52 | L10: =K10*0.49 -> 4.6648 | M10: =L10*1.53 -> 7.137144 | N10: 211.7 | O10: 200 | P10: =N10/O10 -> 1.0585 | T10: Santa Isabel | U10: 25 | V10: CH | W10: 46071
A11: CH26IDAC1-H135-10 | B11: Chardonnay | C11: Colchagua | D11: IDAHUE | E11: 1 | F11: 135 | G11: =_xlfn.TEXTAFTER(A11, "-", 2) -> 10 | H11: 46099 | I11: 3.28 | J11: 22.7 | K11: 9.2 | L11: =K11*0.49 -> 4.508 | M11: =L11*1.53 -> 6.89724 | N11: 231.2 | O11: 200 | P11: =N11/O11 -> 1.156 | T11: Mariposa | U11: 7 | V11: SB
A12: CH26IDAC1-H135-11 | B12: Chardonnay | C12: Colchagua | D12: IDAHUE | E12: 1 | F12: 135 | G12: =_xlfn.TEXTAFTER(A12, "-", 2) -> 11 | H12: 26-03-2026 | I12: 3.15 | J12: 23.3 | K12: 8.93 | L12: =K12*0.49 -> 4.3757 | M12: =L12*1.53 -> 6.694821 | N12: 221.6 | O12: 200 | P12: =N12/O12 -> 1.108 | T12: Quebrada | U12: 45 | V12: CH
A13: CH26IDAC1-H135-12 | B13: Chardonnay | C13: Colchagua | D13: IDAHUE | E13: 1 | F13: 135 | G13: =_xlfn.TEXTAFTER(A13, "-", 2) -> 12 | L13: =K13*0.49 -> 0 | M13: =L13*1.53 -> 0 | P13: =N13/O13 -> #DIV/0!
A14: SB26IDAC9-H300-1 | B14: Sauvignon Blanc | C14: Colchagua | D14: IDAHUE | E14: 9 | F14: 300 | G14: =_xlfn.TEXTAFTER(A14, "-", 2) -> 1 | H14: 46044 | I14: 2.73 | J14: 15.4 | K14: 11.43 | L14: =K14*0.49 -> 5.6007 | M14: =L14*1.53 -> 8.569071 | N14: 159.84 | O14: 200 | P14: =N14/O14 -> 0.7992 | T14: Idahue | U14: 1 | V14: CH | W14: 46073
A15: SB26IDAC9-H300-2 | B15: Sauvignon Blanc | C15: Colchagua | D15: IDAHUE | E15: 9 | F15: 300 | G15: =_xlfn.TEXTAFTER(A15, "-", 2) -> 2 | H15: 46050 | I15: 2.93 | J15: 18.4 | K15: 15.38 | L15: =K15*0.49 -> 7.5362 | M15: =L15*1.53 -> 11.530386 | N15: 196.74 | O15: 200 | P15: =N15/O15 -> 0.9837 | T15: Idahue | U15: 9 | V15: SB | W15: 46070
A16: SB26IDAC9-H300-3 | B16: Sauvignon Blanc | C16: Colchagua | D16: IDAHUE | E16: 9 | F16: 300 | G16: =_xlfn.TEXTAFTER(A16, "-", 2) -> 3 | H16: 46057 | I16: 2.98 | J16: 19.8 | K16: 10.56 | L16: =K16*0.49 -> 5.1744 | M16: =L16*1.53 -> 7.916832 | N16: 221.3 | O16: 200 | P16: =N16/O16 -> 1.1065 | T16: Nilahue | U16: 2 | V16: CS
A17: SB26IDAC9-H300-4 | B17: Sauvignon Blanc | C17: Colchagua | D17: IDAHUE | E17: 9 | F17: 300 | G17: =_xlfn.TEXTAFTER(A17, "-", 2) -> 4 | H17: 46064 | I17: 3.13 | J17: 21.9 | K17: 8.8 | L17: =K17*0.49 -> 4.312 | M17: =L17*1.53 -> 6.59736 | N17: 234.2 | O17: 200 | P17: =N17/O17 -> 1.171 | T17: Peumo | U17: 93 | V17: CA | W17: 28/04/2026
A18: SB26IDAC9-H300-5 | B18: Sauvignon Blanc | C18: Colchagua | D18: IDAHUE | E18: 9 | F18: 300 | G18: =_xlfn.TEXTAFTER(A18, "-", 2) -> 5 | H18: 46071 | I18: 3.21 | J18: 23.9 | K18: 8.86 | L18: =K18*0.49 -> 4.3414 | M18: =L18*1.53 -> 6.642342 | N18: 229.2 | O18: 200 | P18: =N18/O18 -> 1.146 | T18: Keule | U18: 3 | V18: CS | W18: 14/03/2026
A19: SB26IDAC9-H300-6 | B19: Sauvignon Blanc | C19: Colchagua | D19: IDAHUE | E19: 9 | F19: 300 | G19: =_xlfn.TEXTAFTER(A19, "-", 2) -> 6 | H19: 46078 | I19: 3.27 | J19: 24.8 | K19: 7.66 | L19: =K19*0.49 -> 3.7534 | M19: =L19*1.53 -> 5.742702 | N19: 200.9 | O19: 200 | P19: =N19/O19 -> 1.0045 | T19: Villa Alegre | U19: 13 | V19: CA
A20: SB26IDAC9-H300-7 | B20: Sauvignon Blanc | C20: Colchagua | D20: IDAHUE | E20: 9 | F20: 300 | G20: =_xlfn.TEXTAFTER(A20, "-", 2) -> 7 | H20: 46085 | I20: 3.32 | J20: 25.2 | K20: 6.45 | L20: =K20*0.49 -> 3.1605 | M20: =L20*1.53 -> 4.835565 | N20: 194.6 | O20: 200 | P20: =N20/O20 -> 0.973 | T20: Lourdes | U20: 207 | V20: CS
A21: SB26IDAC9-H300-8 | B21: Sauvignon Blanc | C21: Colchagua | D21: IDAHUE | E21: 9 | F21: 300 | G21: =_xlfn.TEXTAFTER(A21, "-", 2) -> 8 | H21: 46092 | I21: 3.26 | J21: 26 | K21: 6.37 | L21: =K21*0.49 -> 3.1213 | M21: =L21*1.53 -> 4.775589 | N21: 188.7 | O21: 200 | P21: =N21/O21 -> 0.9435 | T21: Lourdes | U21: 171 | V21: CA
A22: SB26IDAC9-H300-9 | B22: Sauvignon Blanc | C22: Colchagua | D22: IDAHUE | E22: 9 | F22: 300 | G22: =_xlfn.TEXTAFTER(A22, "-", 2) -> 9 | H22: 46099 | I22: 3.44 | J22: 25.5 | K22: 6.48 | L22: =K22*0.49 -> 3.1752 | M22: =L22*1.53 -> 4.858056 | N22: 208.9 | O22: 200 | P22: =N22/O22 -> 1.0445 | T22: Quinta de Maipo | U22: 1 | V22: CA
A23: SB26IDAC9-H300-10 | B23: Sauvignon Blanc | C23: Colchagua | D23: IDAHUE | E23: 9 | F23: 300 | G23: =_xlfn.TEXTAFTER(A23, "-", 2) -> 10 | H23: 26-03-2026 | I23: 3.19 | J23: 25.7 | K23: 6.62 | L23: =K23*0.49 -> 3.2438 | M23: =L23*1.53 -> 4.963014 | N23: 199.3 | O23: 200 | P23: =N23/O23 -> 0.9965 | T23: San Adolfo | U23: 9 | V23: CS
A24: SB26IDAC9-H300-11 | B24: Sauvignon Blanc | C24: Colchagua | D24: IDAHUE | E24: 9 | F24: 300 | G24: =_xlfn.TEXTAFTER(A24, "-", 2) -> 11 | T24: Palo Santo | U24: 42 | V24: CA | W24: 28/04/2026
A25: CH26UCUC92-H110-1 | B25: Chardonnay | C25: Colchagua | D25: UCUQUER | E25: 92 | F25: 110 | G25: =_xlfn.TEXTAFTER(A25, "-", 2) -> 1 | H25: 46043 | I25: 2.94 | J25: 14.3 | K25: 18.48 | L25: =K25*0.49 -> 9.0552 | M25: =L25*1.53 -> 13.854456 | N25: 244.81 | O25: 200 | P25: =N25/O25 -> 1.22405 | T25: Quebrada de agua | U25: 40 | V25: CS
A26: CH26UCUC92-H110-2 | B26: Chardonnay | C26: Colchagua | D26: UCUQUER | E26: 92 | F26: 110 | G26: =_xlfn.TEXTAFTER(A26, "-", 2) -> 2 | H26: 46049 | I26: 2.85 | J26: 15.6 | K26: 19.6 | L26: =K26*0.49 -> 9.604 | M26: =L26*1.53 -> 14.69412 | N26: 263.66 | O26: 200 | P26: =N26/O26 -> 1.3183 | T26: Rucahue | U26: 24 | V26: CA | W26: 21/04/2026
A27: CH26UCUC92-H110-3 | B27: Chardonnay | C27: Colchagua | D27: UCUQUER | E27: 92 | F27: 110 | G27: =_xlfn.TEXTAFTER(A27, "-", 2) -> 3 | H27: 46056 | I27: 2.96 | J27: 17.3 | K27: 14.66 | L27: =K27*0.49 -> 7.1834 | M27: =L27*1.53 -> 10.990602 | N27: 268.4 | O27: 200 | P27: =N27/O27 -> 1.342
A28: CH26UCUC92-H110-4 | B28: Chardonnay | C28: Colchagua | D28: UCUQUER | E28: 92 | F28: 110 | G28: =_xlfn.TEXTAFTER(A28, "-", 2) -> 4 | H28: 46063 | I28: 3.12 | J28: 19.8 | K28: 12.12 | L28: =K28*0.49 -> 5.9388 | M28: =L28*1.53 -> 9.086364 | N28: 277.4 | O28: 200 | P28: =N28/O28 -> 1.387
A29: CH26UCUC92-H110-5 | B29: Chardonnay | C29: Colchagua | D29: UCUQUER | E29: 92 | F29: 110 | G29: =_xlfn.TEXTAFTER(A29, "-", 2) -> 5 | H29: 46070 | I29: 3.16 | J29: 21.7 | K29: 11.3 | L29: =K29*0.49 -> 5.537 | M29: =L29*1.53 -> 8.47161 | N29: 281 | O29: 200 | P29: =N29/O29 -> 1.405
A30: CH26UCUC92-H110-6 | B30: Chardonnay | C30: Colchagua | D30: UCUQUER | E30: 92 | F30: 110 | G30: =_xlfn.TEXTAFTER(A30, "-", 2) -> 6 | H30: 46077 | I30: 3.14 | J30: 23.1 | K30: 10.02 | L30: =K30*0.49 -> 4.9098 | M30: =L30*1.53 -> 7.511994 | N30: 278.8 | O30: 200 | P30: =N30/O30 -> 1.394
A31: CH26UCUC92-H110-7 | B31: Chardonnay | C31: Colchagua | D31: UCUQUER | E31: 92 | F31: 110 | G31: =_xlfn.TEXTAFTER(A31, "-", 2) -> 7 | H31: 46084 | I31: 3.16 | J31: 23.4 | K31: 9.55 | L31: =K31*0.49 -> 4.6795 | M31: =L31*1.53 -> 7.159635 | N31: 277.7 | O31: 200 | P31: =N31/O31 -> 1.3885 | T31: Cosecha comercial blancos
A32: CH26UCUC92-H110-8 | B32: Chardonnay | C32: Colchagua | D32: UCUQUER | E32: 92 | F32: 110 | G32: =_xlfn.TEXTAFTER(A32, "-", 2) -> 8 | H32: 46091 | I32: 3.11 | J32: 25.1 | K32: 9.23 | L32: =K32*0.49 -> 4.5227 | M32: =L32*1.53 -> 6.919731 | N32: 249.6 | O32: 200 | P32: =N32/O32 -> 1.248
A33: CH26UCUC92-H110-9 | B33: Chardonnay | C33: Colchagua | D33: UCUQUER | E33: 92 | F33: 110 | G33: =_xlfn.TEXTAFTER(A33, "-", 2) -> 9 | H33: 46098 | I33: 3.21 | J33: 23.6 | K33: 8.66 | L33: =K33*0.49 -> 4.2434 | M33: =L33*1.53 -> 6.492402 | N33: 248.4 | O33: 200 | P33: =N33/O33 -> 1.242 | T33: Fundo | U33: Cuartel | V33: Variedad | W33: Fecha cosecha
A34: CH26UCUC92-H110-10 | B34: Chardonnay | C34: Colchagua | D34: UCUQUER | E34: 92 | F34: 110 | G34: =_xlfn.TEXTAFTER(A34, "-", 2) -> 10 | H34: - | I34: 3.2 | J34: 25.8 | K34: 8.34 | L34: =K34*0.49 -> 4.0866 | M34: =L34*1.53 -> 6.252498 | N34: 252.5 | O34: 200 | P34: =N34/O34 -> 1.2625 | T34: Idahue | U34: 1 | V34: CH | W34: 46073
A35: CH26UCUC92-H110-11 | B35: Chardonnay | C35: Colchagua | D35: UCUQUER | E35: 92 | F35: 110 | G35: =_xlfn.TEXTAFTER(A35, "-", 2) -> 11 | H35: 46112 | I35: 3.26 | J35: 25.8 | K35: 7.43 | L35: =K35*0.49 -> 3.6407 | M35: =L35*1.53 -> 5.570271 | N35: 264.3 | O35: 200 | P35: =N35/O35 -> 1.3215 | U35: 9 | V35: SB | W35: 46070
A36: CH26UCUC92-H110-12 | B36: Chardonnay | C36: Colchagua | D36: UCUQUER | E36: 92 | F36: 110 | G36: 12 | H36: 46119 | I36: 3.18 | J36: 26.2 | K36: 7.49 | L36: =K36*0.49 -> 3.6701 | M36: =L36*1.53 -> 5.615253 | N36: 260 | O36: 200 | P36: =N36/O36 -> 1.3 | T36: Ucuquer | U36: 92 | V36: CH | W36: 46098
A37: CH26UCUC92-H110-13 | B37: Chardonnay | C37: Colchagua | D37: UCUQUER | E37: 92 | F37: 110 | G37: 13 | H37: 46126 | I37: 3.43 | J37: 25.7 | K37: 5.16 | L37: =K37*0.49 -> 2.5284 | M37: =L37*1.53 -> 3.868452 | N37: 293 | O37: 200 | P37: =N37/O37 -> 1.465 | Q37: *muestras congeladas | U37: 54 | V37: SB | W37: 46145
A38: CH26UCUC92-H110-14 | B38: Chardonnay | C38: Colchagua | D38: UCUQUER | E38: 92 | F38: 110 | G38: 14 | H38: 46132 | I38: 3.26 | J38: 26.1 | K38: 8.5 | L38: =K38*0.49 -> 4.165 | M38: =L38*1.53 -> 6.37245 | N38: 285 | O38: 200 | P38: =N38/O38 -> 1.425 | T38: Santa Isabel | U38: 25 | V38: CH | W38: 46091
A39: SB26UCUC54-H85-1 | B39: Sauvignon Blanc | C39: Colchagua | D39: UCUQUER | E39: 54 | F39: 85 | G39: =_xlfn.TEXTAFTER(A39, "-", 2) -> 1 | H39: 46043 | I39: 2.77 | J39: 12.2 | K39: 26.1 | L39: =K39*0.49 -> 12.789 | M39: =L39*1.53 -> 19.56717 | N39: 310.26 | O39: 200 | P39: =N39/O39 -> 1.5513 | U39: 27 | V39: SB | W39: 46071
A40: SB26UCUC54-H85-2 | B40: Sauvignon Blanc | C40: Colchagua | D40: UCUQUER | E40: 54 | F40: 85 | G40: =_xlfn.TEXTAFTER(A40, "-", 2) -> 2 | H40: 46049 | I40: 2.72 | J40: 14.8 | K40: 28.48 | L40: =K40*0.49 -> 13.9552 | M40: =L40*1.53 -> 21.351456 | N40: 325.36 | O40: 200 | P40: =N40/O40 -> 1.6268 | T40: San Ignacio | U40: 12 | V40: CH | W40: 46095
...

Sheet CH-Idahue
A2: 2025
A3: Id. original muestra | B3: Variedad | C3: Valles | D3: Fundo | E3: Cuartel | F3: Hilera | G3: N°muestra | H3: Fecha | I3: pH | J3: Brix | K3: Acidez Sulfúrica | L3: Acidez Tartárica | M3: Peso baya
A4: CH25IDAC1-H135-1 | B4: Chardonnay | C4: Colchagua | D4: IDAHUE | E4: 1 | F4: 135 | G4: =_xlfn.TEXTAFTER(A4, "-", 2) -> 1 | H4: 45678 | I4: 2.8 | J4: 10.1 | K4: 22.1284 | L4: 33.8565 | M4: 1.07
A5: CH25IDAC1-H135-2 | B5: Chardonnay | C5: Colchagua | D5: IDAHUE | E5: 1 | F5: 135 | G5: =_xlfn.TEXTAFTER(A5, "-", 2) -> 2 | H5: 45684 | I5: 2.74 | J5: 11.7 | K5: 14.7392 | L5: 22.551 | M5: 1.24
A6: CH25IDAC1-H135-3 | B6: Chardonnay | C6: Colchagua | D6: IDAHUE | E6: 1 | F6: 135 | G6: =_xlfn.TEXTAFTER(A6, "-", 2) -> 3 | H6: 45691 | I6: 2.86 | J6: 15.1 | K6: 10.584 | L6: 16.1935 | M6: 1.4
A7: CH25IDAC1-H135-4 | B7: Chardonnay | C7: Colchagua | D7: IDAHUE | E7: 1 | F7: 135 | G7: =_xlfn.TEXTAFTER(A7, "-", 2) -> 4 | H7: 45698 | I7: 2.99 | J7: 17.3 | K7: 8.5358 | L7: 13.0598 | M7: 1.51
A8: CH25IDAC1-H135-5 | B8: Chardonnay | C8: Colchagua | D8: IDAHUE | E8: 1 | F8: 135 | G8: =_xlfn.TEXTAFTER(A8, "-", 2) -> 5 | H8: 45705 | I8: 3.08 | J8: 19.4 | K8: 7.1638 | L8: 10.9606 | M8: 1.45
A9: CH25IDAC1-H135-6 | B9: Chardonnay | C9: Colchagua | D9: IDAHUE | E9: 1 | F9: 135 | G9: =_xlfn.TEXTAFTER(A9, "-", 2) -> 6 | H9: 45712 | I9: 3.2 | J9: 21 | K9: 6.1936 | L9: 8.4762 | M9: 1.5
A10: CH25IDAC1-H135-7 | B10: Chardonnay | C10: Colchagua | D10: IDAHUE | E10: 1 | F10: 135 | G10: =_xlfn.TEXTAFTER(A10, "-", 2) -> 7 | H10: 45719 | I10: 3.34 | J10: 22.5 | K10: 5.8702 | L10: 8.9814 | M10: 1.6
A11: CH25IDAC1-H135-8 | B11: Chardonnay | C11: Colchagua | D11: IDAHUE | E11: 1 | F11: 135 | G11: =_xlfn.TEXTAFTER(A11, "-", 2) -> 8 | H11: 45726 | I11: 3.31 | J11: 21.6 | K11: 4.9882 | L11: 7.6319 | M11: 1.39
A12: CH25IDAC1-H135-9 | B12: Chardonnay | C12: Colchagua | D12: IDAHUE | E12: 1 | F12: 135 | G12: =_xlfn.TEXTAFTER(A12, "-", 2) -> 9 | H12: 45733 | I12: 3.54 | J12: 26.1 | K12: 4.5815 | L12: 7.0097 | M12: 1.28
A14: 2026
A15: Id. original muestra | B15: Variedad | C15: Valles | D15: Fundo | E15: Cuartel | F15: Hilera | G15: N° muestra | H15: Fecha | I15: pH | J15: Brix | K15: Acidez Sulfúrica | L15: Acidez Tartárica | M15: Peso baya
A16: ='Tabla general'!A2 -> CH26IDAC1-H135-1 | B16: ='Tabla general'!B2 -> Chardonnay | C16: ='Tabla general'!C2 -> Colchagua | D16: ='Tabla general'!D2 -> IDAHUE | E16: ='Tabla general'!E2 -> 1 | F16: ='Tabla general'!F2 -> 135 | G16: ='Tabla general'!G2 -> 1 | H16: ='Tabla general'!H2 -> 46035 | ... J16: ='Tabla general'!J2 -> 9.7 | K16: ='Tabla general'!K2*0.49 -> 18.2966 | L16: ='Tabla general'!L2*1.53 -> 27.993798 | M16: ='Tabla general'!N2/'Tabla general'!O2 -> 0.96225
A17: ='Tabla general'!A3 -> CH26IDAC1-H135-2 | B17: ='Tabla general'!B3 -> Chardonnay | C17: ='Tabla general'!C3 -> Colchagua | D17: ='Tabla general'!D3 -> IDAHUE | E17: ='Tabla general'!E3 -> 1 | F17: ='Tabla general'!F3 -> 135 | G17: ='Tabla general'!G3 -> 2 | H17: ='Tabla general'!H3 -> 46044 | ... J17: ='Tabla general'!J3 -> 12.6 | K17: ='Tabla general'!K3*0.49 -> 6.7767 | L17: ='Tabla general'!L3*1.53 -> 10.368351 | M17: ='Tabla general'!N3/'Tabla general'!O3 -> 0.9448
A18: ='Tabla general'!A4 -> CH26IDAC1-H135-3 | B18: ='Tabla general'!B4 -> Chardonnay | C18: ='Tabla general'!C4 -> Colchagua | D18: ='Tabla general'!D4 -> IDAHUE | E18: ='Tabla general'!E4 -> 1 | F18: ='Tabla general'!F4 -> 135 | G18: ='Tabla general'!G4 -> 3 | H18: ='Tabla general'!H4 -> 46050 | ... J18: ='Tabla general'!J4 -> 14.6 | K18: ='Tabla general'!K4*0.49 -> 9.3296 | L18: ='Tabla general'!L4*1.53 -> 14.274288 | M18: ='Tabla general'!N4/'Tabla general'!O4 -> 1.0426
A19: ='Tabla general'!A5 -> CH26IDAC1-H135-4 | B19: ='Tabla general'!B5 -> Chardonnay | C19: ='Tabla general'!C5 -> Colchagua | D19: ='Tabla general'!D5 -> IDAHUE | E19: ='Tabla general'!E5 -> 1 | F19: ='Tabla general'!F5 -> 135 | G19: ='Tabla general'!G5 -> 4 | H19: ='Tabla general'!H5 -> 46057 | ... J19: ='Tabla general'!J5 -> 16 | K19: ='Tabla general'!K5*0.49 -> 7.9282 | L19: ='Tabla general'!L5*1.53 -> 12.130146 | M19: ='Tabla general'!N5/'Tabla general'!O5 -> 1.126
A20: ='Tabla general'!A6 -> CH26IDAC1-H135-5 | B20: ='Tabla general'!B6 -> Chardonnay | C20: ='Tabla general'!C6 -> Colchagua | D20: ='Tabla general'!D6 -> IDAHUE | E20: ='Tabla general'!E6 -> 1 | F20: ='Tabla general'!F6 -> 135 | G20: ='Tabla general'!G6 -> 5 | H20: ='Tabla general'!H6 -> 46064 | ... J20: ='Tabla general'!J6 -> 18 | K20: ='Tabla general'!K6*0.49 -> 6.8796 | L20: ='Tabla general'!L6*1.53 -> 10.525788 | M20: ='Tabla general'!N6/'Tabla general'!O6 -> 1.212
A21: ='Tabla general'!A7 -> CH26IDAC1-H135-6 | B21: ='Tabla general'!B7 -> Chardonnay | C21: ='Tabla general'!C7 -> Colchagua | D21: ='Tabla general'!D7 -> IDAHUE | E21: ='Tabla general'!E7 -> 1 | F21: ='Tabla general'!F7 -> 135 | G21: ='Tabla general'!G7 -> 6 | H21: ='Tabla general'!H7 -> 46071 | ... J21: ='Tabla general'!J7 -> 19.5 | K21: ='Tabla general'!K7*0.49 -> 6.272 | L21: ='Tabla general'!L7*1.53 -> 9.59616 | M21: ='Tabla general'!N7/'Tabla general'!O7 -> 1.15
A22: ='Tabla general'!A8 -> CH26IDAC1-H135-7 | B22: ='Tabla general'!B8 -> Chardonnay | C22: ='Tabla general'!C8 -> Colchagua | D22: ='Tabla general'!D8 -> IDAHUE | E22: ='Tabla general'!E8 -> 1 | F22: ='Tabla general'!F8 -> 135 | G22: ='Tabla general'!G8 -> 7 | H22: ='Tabla general'!H8 -> 46078 | ... J22: ='Tabla general'!J8 -> 21.3 | K22: ='Tabla general'!K8*0.49 -> 5.0568 | L22: ='Tabla general'!L8*1.53 -> 7.736904 | M22: ='Tabla general'!N8/'Tabla general'!O8 -> 1.186
A23: ='Tabla general'!A9 -> CH26IDAC1-H135-8 | B23: ='Tabla general'!B9 -> Chardonnay | C23: ='Tabla general'!C9 -> Colchagua | D23: ='Tabla general'!D9 -> IDAHUE | E23: ='Tabla general'!E9 -> 1 | F23: ='Tabla general'!F9 -> 135 | G23: ='Tabla general'!G9 -> 8 | H23: ='Tabla general'!H9 -> 46085 | ... J23: ='Tabla general'!J9 -> 21.7 | K23: ='Tabla general'!K9*0.49 -> 5.0127 | L23: ='Tabla general'!L9*1.53 -> 7.669431 | M23: ='Tabla general'!N9/'Tabla general'!O9 -> 1.1625
A24: ='Tabla general'!A10 -> CH26IDAC1-H135-9 | B24: ='Tabla general'!B10 -> Chardonnay | C24: ='Tabla general'!C10 -> Colchagua | D24: ='Tabla general'!D10 -> IDAHUE | E24: ='Tabla general'!E10 -> 1 | F24: ='Tabla general'!F10 -> 135 | G24: ='Tabla general'!G10 -> 9 | H24: ='Tabla general'!H10 -> 46092 | ... J24: ='Tabla general'!J10 -> 22.8 | K24: ='Tabla general'!K10*0.49 -> 4.6648 | L24: ='Tabla general'!L10*1.53 -> 7.137144 | M24: ='Tabla general'!N10/'Tabla general'!O10 -> 1.0585
A25: ='Tabla general'!A11 -> CH26IDAC1-H135-10 | B25: ='Tabla general'!B11 -> Chardonnay | C25: ='Tabla general'!C11 -> Colchagua | D25: ='Tabla general'!D11 -> IDAHUE | E25: ='Tabla general'!E11 -> 1 | F25: ='Tabla general'!F11 -> 135 | G25: ='Tabla general'!G11 -> 10 | H25: ='Tabla general'!H11 -> 46099 | ... J25: ='Tabla general'!J11 -> 22.7 | K25: ='Tabla general'!K11*0.49 -> 4.508 | L25: ='Tabla general'!L11*1.53 -> 6.89724 | M25: ='Tabla general'!N11/'Tabla general'!O11 -> 1.156
A26: ='Tabla general'!A12 -> CH26IDAC1-H135-11 | B26: ='Tabla general'!B12 -> Chardonnay | C26: ='Tabla general'!C12 -> Colchagua | D26: ='Tabla general'!D12 -> IDAHUE | E26: ='Tabla general'!E12 -> 1 | F26: ='Tabla general'!F12 -> 135 | G26: ='Tabla general'!G12 -> 11 | H26: ='Tabla general'!H12 -> 26-03-2026 | ... J26: ='Tabla general'!J12 -> 23.3 | K26: ='Tabla general'!K12*0.49 -> 4.3757 | L26: ='Tabla general'!L12*1.53 -> 6.694821 | M26: ='Tabla general'!N12/'Tabla general'!O12 -> 1.108

Sheet SB-Idahue
A2: 2025
A3: Id. original muestra | B3: Variedad | C3: Valles | D3: Fundo | E3: Cuartel | F3: Hilera | G3: N°muestra | H3: Fecha | I3: pH | J3: Brix | K3: Acidez Sulfúrica | L3: Acidez Tartárica | M3: Peso baya
A4: SB25IDAC9-H300-1 | B4: Sauvignon Blanc | C4: Colchagua | D4: IDAHUE | E4: 9 | F4: 300 | G4: =_xlfn.TEXTAFTER(A4, "-", 2) -> 1 | H4: 45678 | I4: 2.66 | J4: 12.6 | K4: 17.5616 | L4: 26.8692 | M4: 0.77
A5: SB25IDAC9-H300-2 | B5: Sauvignon Blanc | C5: Colchagua | D5: IDAHUE | E5: 9 | F5: 300 | G5: =_xlfn.TEXTAFTER(A5, "-", 2) -> 2 | H5: 45684 | I5: 2.62 | J5: 15.3 | K5: 10.78 | L5: 16.4934 | M5: 0.92
A6: SB25IDAC9-H300-3 | B6: Sauvignon Blanc | C6: Colchagua | D6: IDAHUE | E6: 9 | F6: 300 | G6: =_xlfn.TEXTAFTER(A6, "-", 2) -> 3 | H6: 45691 | I6: 2.7 | J6: 15.8 | K6: 8.1144 | L6: 12.415 | M6: 0.95
A7: SB25IDAC9-H300-4 | B7: Sauvignon Blanc | C7: Colchagua | D7: IDAHUE | E7: 9 | F7: 300 | G7: =_xlfn.TEXTAFTER(A7, "-", 2) -> 4 | H7: 45698 | I7: 2.87 | J7: 17 | K7: 5.6938 | L7: 8.7115 | M7: 1.19
A8: SB25IDAC9-H300-5 | B8: Sauvignon Blanc | C8: Colchagua | D8: IDAHUE | E8: 9 | F8: 300 | G8: =_xlfn.TEXTAFTER(A8, "-", 2) -> 5 | H8: 45705 | I8: 2.98 | J8: 19.5 | K8: 4.5178 | L8: 6.9122 | M8: 1.28
A9: SB25IDAC9-H300-6 | B9: Sauvignon Blanc | C9: Colchagua | D9: IDAHUE | E9: 9 | F9: 300 | G9: =_xlfn.TEXTAFTER(A9, "-", 2) -> 6 | H9: 45712 | I9: 3.06 | J9: 20.7 | K9: 4.655 | L9: 7.1222 | M9: 1.26
A10: SB25IDAC9-H300-7 | B10: Sauvignon Blanc | C10: Colchagua | D10: IDAHUE | E10: 9 | F10: 300 | G10: =_xlfn.TEXTAFTER(A10, "-", 2) -> 7 | H10: 45719 | I10: 3.14 | J10: 22.2 | K10: 3.7828 | L10: 5.7877 | M10: 1.21
A11: SB25IDAC9-H300-8 | B11: Sauvignon Blanc | C11: Colchagua | D11: IDAHUE | E11: 9 | F11: 300 | G11: =_xlfn.TEXTAFTER(A11, "-", 2) -> 8 | H11: 45726 | I11: 3.18 | J11: 22.4 | K11: 3.6554 | L11: 5.5928 | M11: 0.91
A12: SB25IDAC9-H300-9 | B12: Sauvignon Blanc | C12: Colchagua | D12: IDAHUE | E12: 9 | F12: 300 | G12: =_xlfn.TEXTAFTER(A12, "-", 2) -> 9 | H12: 45733 | I12: 3.38 | J12: 23.9 | K12: 3.2291 | L12: 4.9405 | M12: 1.03
A14: 2026
A15: Id. original muestra | B15: Variedad | C15: Valles | D15: Fundo | E15: Cuartel | F15: Hilera | G15: N° muestra | H15: Fecha | I15: pH | J15: Brix | K15: Acidez Sulfúrica | L15: Acidez Tartárica | M15: Peso baya
A16: ='Tabla general'!A14 -> SB26IDAC9-H300-1 | B16: ='Tabla general'!B14 -> Sauvignon Blanc | C16: ='Tabla general'!C14 -> Colchagua | D16: ='Tabla general'!D14 -> IDAHUE | E16: ='Tabla general'!E14 -> 9 | F16: ='Tabla general'!F14 -> 300 | G16: ='Tabla general'!G14 -> 1 | H16: ='Tabla general'!H14 -> 46044 | ... J16: ='Tabla general'!J14 -> 15.4 | K16: ='Tabla general'!K14*0.49 -> 5.6007 | L16: ='Tabla general'!L14*1.53 -> 8.569071 | M16: ='Tabla general'!N14/200 -> 0.7992
A17: ='Tabla general'!A15 -> SB26IDAC9-H300-2 | B17: ='Tabla general'!B15 -> Sauvignon Blanc | C17: ='Tabla general'!C15 -> Colchagua | D17: ='Tabla general'!D15 -> IDAHUE | E17: ='Tabla general'!E15 -> 9 | F17: ='Tabla general'!F15 -> 300 | G17: ='Tabla general'!G15 -> 2 | H17: ='Tabla general'!H15 -> 46050 | ... J17: ='Tabla general'!J15 -> 18.4 | K17: ='Tabla general'!K15*0.49 -> 7.5362 | L17: ='Tabla general'!L15*1.53 -> 11.530386 | M17: ='Tabla general'!N15/200 -> 0.9837
A18: ='Tabla general'!A16 -> SB26IDAC9-H300-3 | B18: ='Tabla general'!B16 -> Sauvignon Blanc | C18: ='Tabla general'!C16 -> Colchagua | D18: ='Tabla general'!D16 -> IDAHUE | E18: ='Tabla general'!E16 -> 9 | F18: ='Tabla general'!F16 -> 300 | G18: ='Tabla general'!G16 -> 3 | H18: ='Tabla general'!H16 -> 46057 | ... J18: ='Tabla general'!J16 -> 19.8 | K18: ='Tabla general'!K16*0.49 -> 5.1744 | L18: ='Tabla general'!L16*1.53 -> 7.916832 | M18: ='Tabla general'!N16/200 -> 1.1065
A19: ='Tabla general'!A17 -> SB26IDAC9-H300-4 | B19: ='Tabla general'!B17 -> Sauvignon Blanc | C19: ='Tabla general'!C17 -> Colchagua | D19: ='Tabla general'!D17 -> IDAHUE | E19: ='Tabla general'!E17 -> 9 | F19: ='Tabla general'!F17 -> 300 | G19: ='Tabla general'!G17 -> 4 | H19: ='Tabla general'!H17 -> 46064 | ... J19: ='Tabla general'!J17 -> 21.9 | K19: ='Tabla general'!K17*0.49 -> 4.312 | L19: ='Tabla general'!L17*1.53 -> 6.59736 | M19: ='Tabla general'!N17/200 -> 1.171
A20: ='Tabla general'!A18 -> SB26IDAC9-H300-5 | B20: ='Tabla general'!B18 -> Sauvignon Blanc | C20: ='Tabla general'!C18 -> Colchagua | D20: ='Tabla general'!D18 -> IDAHUE | E20: ='Tabla general'!E18 -> 9 | F20: ='Tabla general'!F18 -> 300 | G20: ='Tabla general'!G18 -> 5 | H20: ='Tabla general'!H18 -> 46071 | ... J20: ='Tabla general'!J18 -> 23.9 | K20: ='Tabla general'!K18*0.49 -> 4.3414 | L20: ='Tabla general'!L18*1.53 -> 6.642342 | M20: ='Tabla general'!N18/200 -> 1.146
A21: ='Tabla general'!A19 -> SB26IDAC9-H300-6 | B21: ='Tabla general'!B19 -> Sauvignon Blanc | C21: ='Tabla general'!C19 -> Colchagua | D21: ='Tabla general'!D19 -> IDAHUE | E21: ='Tabla general'!E19 -> 9 | F21: ='Tabla general'!F19 -> 300 | G21: ='Tabla general'!G19 -> 6 | H21: ='Tabla general'!H19 -> 46078 | ... J21: ='Tabla general'!J19 -> 24.8 | K21: ='Tabla general'!K19*0.49 -> 3.7534 | L21: ='Tabla general'!L19*1.53 -> 5.742702 | M21: ='Tabla general'!N19/200 -> 1.0045
A22: ='Tabla general'!A20 -> SB26IDAC9-H300-7 | B22: ='Tabla general'!B20 -> Sauvignon Blanc | C22: ='Tabla general'!C20 -> Colchagua | D22: ='Tabla general'!D20 -> IDAHUE | E22: ='Tabla general'!E20 -> 9 | F22: ='Tabla general'!F20 -> 300 | G22: ='Tabla general'!G20 -> 7 | H22: ='Tabla general'!H20 -> 46085 | ... J22: ='Tabla general'!J20 -> 25.2 | K22: ='Tabla general'!K20*0.49 -> 3.1605 | L22: ='Tabla general'!L20*1.53 -> 4.835565 | M22: ='Tabla general'!N20/200 -> 0.973
A23: ='Tabla general'!A21 -> SB26IDAC9-H300-8 | B23: ='Tabla general'!B21 -> Sauvignon Blanc | C23: ='Tabla general'!C21 -> Colchagua | D23: ='Tabla general'!D21 -> IDAHUE | E23: ='Tabla general'!E21 -> 9 | F23: ='Tabla general'!F21 -> 300 | G23: ='Tabla general'!G21 -> 8 | H23: ='Tabla general'!H21 -> 46092 | ... J23: ='Tabla general'!J21 -> 26 | K23: ='Tabla general'!K21*0.49 -> 3.1213 | L23: ='Tabla general'!L21*1.53 -> 4.775589 | M23: ='Tabla general'!N21/200 -> 0.9435
A24: ='Tabla general'!A22 -> SB26IDAC9-H300-9 | B24: ='Tabla general'!B22 -> Sauvignon Blanc | C24: ='Tabla general'!C22 -> Colchagua | D24: ='Tabla general'!D22 -> IDAHUE | E24: ='Tabla general'!E22 -> 9 | F24: ='Tabla general'!F22 -> 300 | G24: ='Tabla general'!G22 -> 9 | H24: ='Tabla general'!H22 -> 46099 | ... J24: ='Tabla general'!J22 -> 25.5 | K24: ='Tabla general'!K22*0.49 -> 3.1752 | L24: ='Tabla general'!L22*1.53 -> 4.858056 | M24: ='Tabla general'!N22/200 -> 1.0445
A25: ='Tabla general'!A23 -> SB26IDAC9-H300-10 | B25: ='Tabla general'!B23 -> Sauvignon Blanc | C25: ='Tabla general'!C23 -> Colchagua | D25: ='Tabla general'!D23 -> IDAHUE | E25: ='Tabla general'!E23 -> 9 | F25: ='Tabla general'!F23 -> 300 | G25: ='Tabla general'!G23 -> 10 | H25: ='Tabla general'!H23 -> 26-03-2026 | ... J25: ='Tabla general'!J23 -> 25.7 | K25: ='Tabla general'!K23*0.49 -> 3.2438 | L25: ='Tabla general'!L23*1.53 -> 4.963014 | M25: ='Tabla general'!N23/200 -> 0.9965

Sheet CH-Ucuquer
A2: 2025
A3: Id. original muestra | B3: Variedad | C3: Valles | D3: Fundo | E3: Cuartel | F3: Hilera | G3: N°muestra | H3: Fecha | I3: pH | J3: Brix | K3: Acidez Sulfúrica | L3: Acidez Tartárica | M3: Peso baya
A4: CH25UCUC92-H110-1 | B4: Chardonnay | C4: Colchagua | D4: UCUQUER | E4: 92 | F4: 110 | G4: =_xlfn.TEXTAFTER(A4, "-", 2) -> 1 | H4: 45678 | I4: 2.7 | J4: 10.1 | K4: 20.727 | L4: 31.7123 | M4: 1.13
A5: CH25UCUC92-H110-2 | B5: Chardonnay | C5: Colchagua | D5: UCUQUER | E5: 92 | F5: 110 | G5: =_xlfn.TEXTAFTER(A5, "-", 2) -> 2 | H5: 45685 | I5: 2.68 | J5: 14.4 | K5: 12.5538 | L5: 19.2073 | M5: 1.25
A6: CH25UCUC92-H110-3 | B6: Chardonnay | C6: Colchagua | D6: UCUQUER | E6: 92 | F6: 110 | G6: =_xlfn.TEXTAFTER(A6, "-", 2) -> 3 | H6: 45692 | I6: 2.78 | J6: 16.5 | K6: 9.9274 | L6: 15.1889 | M6: 1.43
A7: CH25UCUC92-H110-4 | B7: Chardonnay | C7: Colchagua | D7: UCUQUER | E7: 92 | F7: 110 | G7: =_xlfn.TEXTAFTER(A7, "-", 2) -> 4 | H7: 45699 | I7: 2.86 | J7: 17.4 | K7: 7.889 | L7: 12.0702 | M7: 1.61
A8: CH25UCUC92-H110-5 | B8: Chardonnay | C8: Colchagua | D8: UCUQUER | E8: 92 | F8: 110 | G8: =_xlfn.TEXTAFTER(A8, "-", 2) -> 5 | H8: 45706 | I8: 2.93 | J8: 19.4 | K8: 6.7718 | L8: 10.3609 | M8: 1.65
A9: CH25UCUC92-H110-6 | B9: Chardonnay | C9: Colchagua | D9: UCUQUER | E9: 92 | F9: 110 | G9: =_xlfn.TEXTAFTER(A9, "-", 2) -> 6 | H9: 45713 | I9: 3.07 | J9: 20.8 | K9: 6.2524 | L9: 9.5662 | M9: 1.61
A10: CH25UCUC92-H110-7 | B10: Chardonnay | C10: Colchagua | D10: UCUQUER | E10: 92 | F10: 110 | G10: =_xlfn.TEXTAFTER(A10, "-", 2) -> 7 | H10: 45720 | I10: 3.17 | J10: 21.8 | K10: 5.3704 | L10: 8.2167 | M10: 1.93
A11: CH25UCUC92-H110-8 | B11: Chardonnay | C11: Colchagua | D11: UCUQUER | E11: 92 | F11: 110 | G11: =_xlfn.TEXTAFTER(A11, "-", 2) -> 8 | H11: 45727 | I11: 3.24 | J11: 22.4 | K11: 5.3214 | L11: 8.1417 | M11: 1.91
A12: CH25UCUC92-H110-9 | B12: Chardonnay | C12: Colchagua | D12: UCUQUER | E12: 92 | F12: 110 | G12: =_xlfn.TEXTAFTER(A12, "-", 2) -> 9 | H12: 45733 | I12: 3.25 | J12: 23.3 | K12: 4.9931 | L12: 7.6394 | M12: 1.67
A14: 2026
A15: Id. original muestra | B15: Variedad | C15: Valles | D15: Fundo | E15: Cuartel | F15: Hilera | G15: N°muestra | H15: Fecha | I15: pH | J15: Brix | K15: Acidez Sulfúrica | L15: Acidez Tartárica | M15: Peso baya
A16: ='Tabla general'!A25 -> CH26UCUC92-H110-1 | B16: ='Tabla general'!B25 -> Chardonnay | C16: ='Tabla general'!C25 -> Colchagua | D16: ='Tabla general'!D25 -> UCUQUER | E16: ='Tabla general'!E25 -> 92 | F16: ='Tabla general'!F25 -> 110 | G16: ='Tabla general'!G25 -> 1 | H16: ='Tabla general'!H25 -> 46043 | ... J16: ='Tabla general'!J25 -> 14.3 | K16: ='Tabla general'!K25*0.49 -> 9.0552 | L16: ='Tabla general'!L25*1.53 -> 13.854456 | M16: ='Tabla general'!N25/200 -> 1.22405
A17: ='Tabla general'!A26 -> CH26UCUC92-H110-2 | B17: ='Tabla general'!B26 -> Chardonnay | C17: ='Tabla general'!C26 -> Colchagua | D17: ='Tabla general'!D26 -> UCUQUER | E17: ='Tabla general'!E26 -> 92 | F17: ='Tabla general'!F26 -> 110 | G17: ='Tabla general'!G26 -> 2 | H17: ='Tabla general'!H26 -> 46049 | ... J17: ='Tabla general'!J26 -> 15.6 | K17: ='Tabla general'!K26*0.49 -> 9.604 | L17: ='Tabla general'!L26*1.53 -> 14.69412 | M17: ='Tabla general'!N26/200 -> 1.3183
A18: ='Tabla general'!A27 -> CH26UCUC92-H110-3 | B18: ='Tabla general'!B27 -> Chardonnay | C18: ='Tabla general'!C27 -> Colchagua | D18: ='Tabla general'!D27 -> UCUQUER | E18: ='Tabla general'!E27 -> 92 | F18: ='Tabla general'!F27 -> 110 | G18: ='Tabla general'!G27 -> 3 | H18: ='Tabla general'!H27 -> 46056 | ... J18: ='Tabla general'!J27 -> 17.3 | K18: ='Tabla general'!K27*0.49 -> 7.1834 | L18: ='Tabla general'!L27*1.53 -> 10.990602 | M18: ='Tabla general'!N27/200 -> 1.342
A19: ='Tabla general'!A28 -> CH26UCUC92-H110-4 | B19: ='Tabla general'!B28 -> Chardonnay | C19: ='Tabla general'!C28 -> Colchagua | D19: ='Tabla general'!D28 -> UCUQUER | E19: ='Tabla general'!E28 -> 92 | F19: ='Tabla general'!F28 -> 110 | G19: ='Tabla general'!G28 -> 4 | H19: ='Tabla general'!H28 -> 46063 | ... J19: ='Tabla general'!J28 -> 19.8 | K19: ='Tabla general'!K28*0.49 -> 5.9388 | L19: ='Tabla general'!L28*1.53 -> 9.086364 | M19: ='Tabla general'!N28/200 -> 1.387
A20: ='Tabla general'!A29 -> CH26UCUC92-H110-5 | B20: ='Tabla general'!B29 -> Chardonnay | C20: ='Tabla general'!C29 -> Colchagua | D20: ='Tabla general'!D29 -> UCUQUER | E20: ='Tabla general'!E29 -> 92 | F20: ='Tabla general'!F29 -> 110 | G20: ='Tabla general'!G29 -> 5 | H20: ='Tabla general'!H29 -> 46070 | ... J20: ='Tabla general'!J29 -> 21.7 | K20: ='Tabla general'!K29*0.49 -> 5.537 | L20: ='Tabla general'!L29*1.53 -> 8.47161 | M20: ='Tabla general'!N29/200 -> 1.405
A21: ='Tabla general'!A30 -> CH26UCUC92-H110-6 | B21: ='Tabla general'!B30 -> Chardonnay | C21: ='Tabla general'!C30 -> Colchagua | D21: ='Tabla general'!D30 -> UCUQUER | E21: ='Tabla general'!E30 -> 92 | F21: ='Tabla general'!F30 -> 110 | G21: ='Tabla general'!G30 -> 6 | H21: ='Tabla general'!H30 -> 46077 | ... J21: ='Tabla general'!J30 -> 23.1 | K21: ='Tabla general'!K30*0.49 -> 4.9098 | L21: ='Tabla general'!L30*1.53 -> 7.511994 | M21: ='Tabla general'!N30/200 -> 1.394
A22: ='Tabla general'!A31 -> CH26UCUC92-H110-7 | B22: ='Tabla general'!B31 -> Chardonnay | C22: ='Tabla general'!C31 -> Colchagua | D22: ='Tabla general'!D31 -> UCUQUER | E22: ='Tabla general'!E31 -> 92 | F22: ='Tabla general'!F31 -> 110 | G22: ='Tabla general'!G31 -> 7 | H22: ='Tabla general'!H31 -> 46084 | ... J22: ='Tabla general'!J31 -> 23.4 | K22: ='Tabla general'!K31*0.49 -> 4.6795 | L22: ='Tabla general'!L31*1.53 -> 7.159635 | M22: ='Tabla general'!N31/200 -> 1.3885
A23: ='Tabla general'!A32 -> CH26UCUC92-H110-8 | B23: ='Tabla general'!B32 -> Chardonnay | C23: ='Tabla general'!C32 -> Colchagua | D23: ='Tabla general'!D32 -> UCUQUER | E23: ='Tabla general'!E32 -> 92 | F23: ='Tabla general'!F32 -> 110 | G23: ='Tabla general'!G32 -> 8 | H23: ='Tabla general'!H32 -> 46091 | ... J23: ='Tabla general'!J32 -> 25.1 | K23: ='Tabla general'!K32*0.49 -> 4.5227 | L23: ='Tabla general'!L32*1.53 -> 6.919731 | M23: ='Tabla general'!N32/200 -> 1.248
A24: ='Tabla general'!A33 -> CH26UCUC92-H110-9 | B24: ='Tabla general'!B33 -> Chardonnay | C24: ='Tabla general'!C33 -> Colchagua | D24: ='Tabla general'!D33 -> UCUQUER | E24: ='Tabla general'!E33 -> 92 | F24: ='Tabla general'!F33 -> 110 | G24: ='Tabla general'!G33 -> 9 | H24: ='Tabla general'!H33 -> 46098 | ... J24: ='Tabla general'!J33 -> 23.6 | K24: ='Tabla general'!K33*0.49 -> 4.2434 | L24: ='Tabla general'!L33*1.53 -> 6.492402 | M24: ='Tabla general'!N33/200 -> 1.242
A25: ='Tabla general'!A34 -> CH26UCUC92-H110-10 | B25: ='Tabla general'!B34 -> Chardonnay | C25: ='Tabla general'!C34 -> Colchagua | D25: ='Tabla general'!D34 -> UCUQUER | E25: ='Tabla general'!E34 -> 92 | F25: ='Tabla general'!F34 -> 110 | G25: ='Tabla general'!G34 -> 10 | H25: ='Tabla general'!H34 -> - | ... J25: ='Tabla general'!J34 -> 25.8 | K25: ='Tabla general'!K34*0.49 -> 4.0866 | L25: ='Tabla general'!L34*1.53 -> 6.252498 | M25: ='Tabla general'!N34/200 -> 1.2625
A26: ='Tabla general'!A35 -> CH26UCUC92-H110-11 | B26: ='Tabla general'!B35 -> Chardonnay | C26: ='Tabla general'!C35 -> Colchagua | D26: ='Tabla general'!D35 -> UCUQUER | E26: ='Tabla general'!E35 -> 92 | F26: ='Tabla general'!F35 -> 110 | G26: ='Tabla general'!G35 -> 11 | H26: ='Tabla general'!H35 -> 46112 | ... J26: ='Tabla general'!J35 -> 25.8 | K26: ='Tabla general'!K35*0.49 -> 3.6407 | L26: ='Tabla general'!L35*1.53 -> 5.570271 | M26: ='Tabla general'!N35/200 -> 1.3215
A27: ='Tabla general'!A36 -> CH26UCUC92-H110-12 | B27: ='Tabla general'!B36 -> Chardonnay | C27: ='Tabla general'!C36 -> Colchagua | D27: ='Tabla general'!D36 -> UCUQUER | E27: ='Tabla general'!E36 -> 92 | F27: ='Tabla general'!F36 -> 110 | G27: ='Tabla general'!G36 -> 12 | H27: ='Tabla general'!H36 -> 46119 | ... J27: ='Tabla general'!J36 -> 26.2 | K27: ='Tabla general'!K36*0.49 -> 3.6701 | L27: ='Tabla general'!L36*1.53 -> 5.615253 | M27: ='Tabla general'!N36/200 -> 1.3
... A29: ='Tabla general'!A38 -> CH26UCUC92-H110-14 | B29: ='Tabla general'!B38 -> Chardonnay | C29: ='Tabla general'!C38 -> Colchagua | D29: ='Tabla general'!D38 -> UCUQUER | E29: ='Tabla general'!E38 -> 92 | F29: ='Tabla general'!F38 -> 110 | G29: ='Tabla general'!G38 -> 14 | H29: ='Tabla general'!H38 -> 46132 | ... J29: ='Tabla general'!J38 -> 26.1 | K29: ='Tabla general'!K38*0.49 -> 4.165 | L29: ='Tabla general'!L38*1.53 -> 6.37245 | M29: ='Tabla general'!N38/200 -> 1.425

Sheet SB-Ucuquer
A2: 2025
A3: Id. original muestra | B3: Variedad | C3: Valles | D3: Fundo | E3: Cuartel | F3: Hilera | G3: N°muestra | H3: Fecha | I3: pH | J3: Brix | K3: Acidez Sulfúrica | L3: Acidez Tartárica | M3: Peso baya
A4: SB25UCUC54-H85-1 | B4: Sauvignon Blanc | C4: Colchagua | D4: UCUQUER | E4: 54 | F4: 85 | G4: =_xlfn.TEXTAFTER(A4, "-", 2) -> 1 | H4: 45678 | I4: 2.53 | J4: 8.9 | K4: 24.9214 | L4: 38.1297 | M4: 1.17
A5: SB25UCUC54-H85-2 | B5: Sauvignon Blanc | C5: Colchagua | D5: UCUQUER | E5: 54 | F5: 85 | G5: =_xlfn.TEXTAFTER(A5, "-", 2) -> 2 | H5: 45685 | I5: 2.51 | J5: 13.1 | K5: 17.7184 | L5: 27.1091 | M5: 1.42
A6: SB25UCUC54-H85-3 | B6: Sauvignon Blanc | C6: Colchagua | D6: UCUQUER | E6: 54 | F6: 85 | G6: =_xlfn.TEXTAFTER(A6, "-", 2) -> 3 | H6: 45692 | I6: 2.57 | J6: 15.2 | K6: 14.8862 | L6: 22.7759 | M6: 1.51
A7: SB25UCUC54-H85-4 | B7: Sauvignon Blanc | C7: Colchagua | D7: UCUQUER | E7: 54 | F7: 85 | G7: =_xlfn.TEXTAFTER(A7, "-", 2) -> 4 | H7: 45699 | I7: 2.67 | J7: 16.5 | K7: 11.0446 | L7: 16.8982 | M7: 1.78
A8: SB25UCUC54-H85-5 | B8: Sauvignon Blanc | C8: Colchagua | D8: UCUQUER | E8: 54 | F8: 85 | G8: =_xlfn.TEXTAFTER(A8, "-", 2) -> 5 | H8: 45706 | I8: 2.75 | J8: 19.4 | K8: 8.8298 | L8: 13.5096 | M8: 1.87
A9: SB25UCUC54-H85-6 | B9: Sauvignon Blanc | C9: Colchagua | D9: UCUQUER | E9: 54 | F9: 85 | G9: =_xlfn.TEXTAFTER(A9, "-", 2) -> 6 | H9: 45713 | I9: 2.95 | J9: 21.2 | K9: 7.1932 | L9: 11.0056 | M9: 1.88
A10: SB25UCUC54-H85-7 | B10: Sauvignon Blanc | C10: Colchagua | D10: UCUQUER | E10: 54 | F10: 85 | G10: =_xlfn.TEXTAFTER(A10, "-", 2) -> 7 | H10: 45720 | I10: 3.03 | J10: 22.6 | K10: 6.6052 | L10: 10.106 | M10: 2.1
A11: SB25UCUC54-H85-8 | B11: Sauvignon Blanc | C11: Colchagua | D11: UCUQUER | E11: 54 | F11: 85 | G11: =_xlfn.TEXTAFTER(A11, "-", 2) -> 8 | H11: 45727 | I11: 3.16 | J11: 25.1 | K11: 5.439 | L11: 8.3217 | M11: 1.86
A12: SB25UCUC54-H85-9 | B12: Sauvignon Blanc | C12: Colchagua | D12: UCUQUER | E12: 54 | F12: 85 | G12: =_xlfn.TEXTAFTER(A12, "-", 2) -> 9 | H12: 45733 | I12: 3.13 | J12: 24.2 | K12: 4.7824 | L12: 7.3171 | M12: 1.65
A14: 2026
A15: Id. original muestra | B15: Variedad | C15: Valles | D15: Fundo | E15: Cuartel | F15: Hilera | G15: N°muestra | H15: Fecha | I15: pH | J15: Brix | K15: Acidez Sulfúrica | L15: Acidez Tartárica | M15: Peso baya
A16: ='Tabla general'!A39 -> SB26UCUC54-H85-1 | B16: ='Tabla general'!B39 -> Sauvignon Blanc | C16: ='Tabla general'!C39 -> Colchagua | D16: ='Tabla general'!D39 -> UCUQUER | E16: ='Tabla general'!E39 -> 54 | F16: ='Tabla general'!F39 -> 85 | G16: ='Tabla general'!G39 -> 1 | H16: ='Tabla general'!H39 -> 46043 | ... J16: ='Tabla general'!J39 -> 12.2 | K16: ='Tabla general'!K39*0.49 -> 12.789 | L16: ='Tabla general'!L39*1.53 -> 19.56717 | M16: ='Tabla general'!N39/200 -> 1.5513
A17: ='Tabla general'!A40 -> SB26UCUC54-H85-2 | B17: ='Tabla general'!B40 -> Sauvignon Blanc | C17: ='Tabla general'!C40 -> Colchagua | D17: ='Tabla general'!D40 -> UCUQUER | E17: ='Tabla general'!E40 -> 54 | F17: ='Tabla general'!F40 -> 85 | G17: ='Tabla general'!G40 -> 2 | H17: ='Tabla general'!H40 -> 46049 | ... J17: ='Tabla general'!J40 -> 14.8 | K17: ='Tabla general'!K40*0.49 -> 13.9552 | L17: ='Tabla general'!L40*1.53 -> 21.351456 | M17: ='Tabla general'!N40/200 -> 1.6268
A18: ='Tabla general'!A41 -> SB26UCUC54-H85-3 | B18: ='Tabla general'!B41 -> Sauvignon Blanc | C18: ='Tabla general'!C41 -> Colchagua | D18: ='Tabla general'!D41 -> UCUQUER | E18: ='Tabla general'!E41 -> 54 | F18: ='Tabla general'!F41 -> 85 | G18: ='Tabla general'!G41 -> 3 | H18: ='Tabla general'!H41 -> 46056 | ... J18: ='Tabla general'!J41 -> 15.9 | K18: ='Tabla general'!K41*0.49 -> 11.466 | L18: ='Tabla general'!L41*1.53 -> 17.54298 | M18: ='Tabla general'!N41/200 -> 1.9035
A19: ='Tabla general'!A42 -> SB26UCUC54-H85-4 | B19: ='Tabla general'!B42 -> Sauvignon Blanc | C19: ='Tabla general'!C42 -> Colchagua | D19: ='Tabla general'!D42 -> UCUQUER | E19: ='Tabla general'!E42 -> 54 | F19: ='Tabla general'!F42 -> 85 | G19: ='Tabla general'!G42 -> 4 | H19: ='Tabla general'!H42 -> 46063 | ... J19: ='Tabla general'!J42 -> 18.5 | K19: ='Tabla general'!K42*0.49 -> 8.7612 | L19: ='Tabla general'!L42*1.53 -> 13.404636 | M19: ='Tabla general'!N42/200 -> 1.963
A20: ='Tabla general'!A43 -> SB26UCUC54-H85-5 | B20: ='Tabla general'!B43 -> Sauvignon Blanc | C20: ='Tabla general'!C43 -> Colchagua | D20: ='Tabla general'!D43 -> UCUQUER | E20: ='Tabla general'!E43 -> 54 | F20: ='Tabla general'!F43 -> 85 | G20: ='Tabla general'!G43 -> 5 | H20: ='Tabla general'!H43 -> 46070 | ... J20: ='Tabla general'!J43 -> 20.5 | K20: ='Tabla general'!K43*0.49 -> 7.5852 | L20: ='Tabla general'!L43*1.53 -> 11.605356 | M20: ='Tabla general'!N43/200 -> 2.0185
A21: ='Tabla general'!A44 -> SB26UCUC54-H85-6 | B21: ='Tabla general'!B44 -> Sauvignon Blanc | C21: ='Tabla general'!C44 -> Colchagua | D21: ='Tabla general'!D44 -> UCUQUER | E21: ='Tabla general'!E44 -> 54 | F21: ='Tabla general'!F44 -> 85 | G21: ='Tabla general'!G44 -> 6 | H21: ='Tabla general'!H44 -> 46077 | ... J21: ='Tabla general'!J44 -> 21.8 | K21: ='Tabla general'!K44*0.49 -> 6.272 | L21: ='Tabla general'!L44*1.53 -> 9.59616 | M21: ='Tabla general'!N44/200 -> 2.0805
A22: ='Tabla general'!A45 -> SB26UCUC54-H85-7 | B22: ='Tabla general'!B45 -> Sauvignon Blanc | C22: ='Tabla general'!C45 -> Colchagua | D22: ='Tabla general'!D45 -> UCUQUER | E22: ='Tabla general'!E45 -> 54 | F22: ='Tabla general'!F45 -> 85 | G22: ='Tabla general'!G45 -> 7 | H22: ='Tabla general'!H45 -> 46084 | ... J22: ='Tabla general'!J45 -> 22.7 | K22: ='Tabla general'!K45*0.49 -> 5.7183 | L22: ='Tabla general'!L45*1.53 -> 8.748999 | M22: ='Tabla general'!N45/200 -> 2.0615
A23: ='Tabla general'!A46 -> SB26UCUC54-H85-8 | B23: ='Tabla general'!B46 -> Sauvignon Blanc | C23: ='Tabla general'!C46 -> Colchagua | D23: ='Tabla general'!D46 -> UCUQUER | E23: ='Tabla general'!E46 -> 54 | F23: ='Tabla general'!F46 -> 85 | G23: ='Tabla general'!G46 -> 8 | H23: ='Tabla general'!H46 -> 46091 | ... J23: ='Tabla general'!J46 -> 24.3 | K23: ='Tabla general'!K46*0.49 -> 5.3508 | L23: ='Tabla general'!L46*1.53 -> 8.186724 | M23: ='Tabla general'!N46/200 -> 1.9615
A24: ='Tabla general'!A47 -> SB26UCUC54-H85-9 | B24: ='Tabla general'!B47 -> Sauvignon Blanc | C24: ='Tabla general'!C47 -> Colchagua | D24: ='Tabla general'!D47 -> UCUQUER | E24: ='Tabla general'!E47 -> 54 | F24: ='Tabla general'!F47 -> 85 | G24: ='Tabla general'!G47 -> 9 | H24: ='Tabla general'!H47 -> 46098 | ... J24: ='Tabla general'!J47 -> 25.5 | K24: ='Tabla general'!K47*0.49 -> 4.5668 | L24: ='Tabla general'!L47*1.53 -> 6.987204 | M24: ='Tabla general'!N47/200 -> 1.981
A25: ='Tabla general'!A48 -> SB26UCUC54-H85-10 | B25: ='Tabla general'!B48 -> Sauvignon Blanc | C25: ='Tabla general'!C48 -> Colchagua | D25: ='Tabla general'!D48 -> UCUQUER | E25: ='Tabla general'!E48 -> 54 | F25: ='Tabla general'!F48 -> 85 | G25: ='Tabla general'!G48 -> 10 | H25: ='Tabla general'!H48 -> - | ... J25: ='Tabla general'!J48 -> 25.7 | K25: ='Tabla general'!K48*0.49 -> 5.0274 | L25: ='Tabla general'!L48*1.53 -> 7.691922 | M25: ='Tabla general'!N48/200 -> 2.012
A26: ='Tabla general'!A49 -> SB26UCUC54-H85-11 | B26: ='Tabla general'!B49 -> Sauvignon Blanc | C26: ='Tabla general'!C49 -> Colchagua | D26: ='Tabla general'!D49 -> UCUQUER | E26: ='Tabla general'!E49 -> 54 | F26: ='Tabla general'!F49 -> 85 | G26: ='Tabla general'!G49 -> 11 | H26: ='Tabla general'!H49 -> 46112 | ... J26: ='Tabla general'!J49 -> 25.8 | K26: ='Tabla general'!K49*0.49 -> 4.3218 | L26: ='Tabla general'!L49*1.53 -> 6.612354 | M26: ='Tabla general'!N49/200 -> 1.9525
A27: ='Tabla general'!A50 -> SB26UCUC54-H85-12 | B27: ='Tabla general'!B50 -> Sauvignon Blanc | C27: ='Tabla general'!C50 -> Colchagua | D27: ='Tabla general'!D50 -> UCUQUER | E27: ='Tabla general'!E50 -> 54 | F27: ='Tabla general'!F50 -> 85 | G27: ='Tabla general'!G50 -> 12 | H27: ='Tabla general'!H50 -> 46119 | ... J27: ='Tabla general'!J50 -> 27.7 | K27: ='Tabla general'!K50*0.49 -> 4.6893 | L27: ='Tabla general'!L50*1.53 -> 7.174629 | M27: ='Tabla general'!N50/200 -> 1.8375
... A29: ='Tabla general'!A52 -> SB26UCUC54-H85-14 | B29: ='Tabla general'!B52 -> Sauvignon Blanc | C29: ='Tabla general'!C52 -> Colchagua | D29: ='Tabla general'!D52 -> UCUQUER | E29: ='Tabla general'!E52 -> 54 | F29: ='Tabla general'!F52 -> 85 | G29: ='Tabla general'!G52 -> 14 | H29: ='Tabla general'!H52 -> 46132 | ... J29: ='Tabla general'!J52 -> 27.8 | K29: ='Tabla general'!K52*0.49 -> 4.4933 | L29: ='Tabla general'!L52*1.53 -> 6.874749 | M29: ='Tabla general'!N52/200 -> 1.94

Sheet SB-Yungay
A2: 2025
A3: Id. original muestra | B3: Variedad | C3: Valles | D3: Fundo | E3: Cuartel | F3: Hilera | G3: N°muestra | H3: Fecha | I3: pH | J3: Brix | K3: Acidez Sulfúrica | L3: Acidez Tartárica | M3: Peso baya
A4: SB25YUNC4-H180-1 | B4: Sauvignon Blanc | C4: Curicó | D4: YUNGAY | E4: 4 | F4: 180 | G4: =_xlfn.TEXTAFTER(A4, "-", 2) -> 1 | H4: 45680 | I4: 2.48 | J4: 8.1 | K4: 25.1468 | L4: 38.4746 | M4: 1.16
A5: SB25YUNC4-H180-2 | B5: Sauvignon Blanc | C5: Curicó | D5: YUNGAY | E5: 4 | F5: 180 | G5: =_xlfn.TEXTAFTER(A5, "-", 2) -> 2 | H5: 45684 | I5: 2.46 | J5: 9.3 | K5: 23.3338 | L5: 35.7007 | M5: 1.23
A6: SB25YUNC4-H180-3 | B6: Sauvignon Blanc | C6: Curicó | D6: YUNGAY | E6: 4 | F6: 180 | G6: =_xlfn.TEXTAFTER(A6, "-", 2) -> 3 | H6: 45691 | I6: 2.69 | J6: 13.7 | K6: 16.9344 | L6: 25.9096 | M6: 1.65
A7: SB25YUNC4-H180-4 | B7: Sauvignon Blanc | C7: Curicó | D7: YUNGAY | E7: 4 | F7: 180 | G7: =_xlfn.TEXTAFTER(A7, "-", 2) -> 4 | H7: 45698 | I7: 2.74 | J7: 16.3 | K7: 12.6322 | L7: 19.3273 | M7: 1.79
A8: SB25YUNC4-H180-5 | B8: Sauvignon Blanc | C8: Curicó | D8: YUNGAY | E8: 4 | F8: 180 | G8: =_xlfn.TEXTAFTER(A8, "-", 2) -> 5 | H8: 45707 | I8: 2.86 | J8: 18.9 | K8: 10.1528 | L8: 15.5338 | M8: 1.86
A9: SB25YUNC4-H180-6 | B9: Sauvignon Blanc | C9: Curicó | D9: YUNGAY | E9: 4 | F9: 180 | G9: =_xlfn.TEXTAFTER(A9, "-", 2) -> 6 | H9: 45714 | I9: 2.87 | J9: 20.4 | K9: 8.8592 | L9: 13.5546 | M9: 1.91
A10: SB25YUNC4-H180-7 | B10: Sauvignon Blanc | C10: Curicó | D10: YUNGAY | E10: 4 | F10: 180 | G10: =_xlfn.TEXTAFTER(A10, "-", 2) -> 7 | H10: 45722 | I10: 3.15 | J10: 21.3 | K10: 7.007 | L10: 10.7207 | M10: 1.97
A11: SB25YUNC4-H180-8 | B11: Sauvignon Blanc | C11: Curicó | D11: YUNGAY | E11: 4 | F11: 180 | G11: =_xlfn.TEXTAFTER(A11, "-", 2) -> 8 | H11: 45728 | I11: 3.22 | J11: 21.9 | K11: 6.517 | L11: 9.971 | M11: 1.97
A12: SB25YUNC4-H180-9 | B12: Sauvignon Blanc | C12: Curicó | D12: YUNGAY | E12: 4 | F12: 180 | G12: =_xlfn.TEXTAFTER(A12, "-", 2) -> 9 | H12: 45734 | I12: 3.25 | J12: 22.6 | K12: 6.1397 | L12: 9.3937 | M12: 2.13
A14: 2026
A15: Id. original muestra | B15: Variedad | C15: Valles | D15: Fundo | E15: Cuartel | F15: Hilera | G15: N°muestra | H15: Fecha | I15: pH | J15: Brix | K15: Acidez Sulfúrica | L15: Acidez Tartárica | M15: Peso baya
A16: ='Tabla general'!A53 -> SB26YUNC4-H180-1 | B16: ='Tabla general'!B53 -> Sauvignon Blanc | C16: ='Tabla general'!C53 -> Curicó | D16: ='Tabla general'!D53 -> YUNGAY | E16: ='Tabla general'!E53 -> 4 | F16: ='Tabla general'!F53 -> 180 | G16: ='Tabla general'!G53 -> 1 | H16: ='Tabla general'!H53 -> 46045 | ... J16: ='Tabla general'!J53 -> 9.1 | K16: ='Tabla general'!K53*0.49 -> 16.6796 | L16: ='Tabla general'!L53*1.53 -> 25.519788 | M16: ='Tabla general'!N53/200 -> 1.2983
A17: ='Tabla general'!A54 -> SB26YUNC4-H180-2 | B17: ='Tabla general'!B54 -> Sauvignon Blanc | C17: ='Tabla general'!C54 -> Curicó | D17: ='Tabla general'!D54 -> YUNGAY | E17: ='Tabla general'!E54 -> 4 | F17: ='Tabla general'!F54 -> 180 | G17: ='Tabla general'!G54 -> 2 | H17: ='Tabla general'!H54 -> 46051 | ... J17: ='Tabla general'!J54 -> 11.2 | K17: ='Tabla general'!K54*0.49 -> 8.3202 | L17: ='Tabla general'!L54*1.53 -> 12.729906 | M17: ='Tabla general'!N54/200 -> 1.4429
A18: ='Tabla general'!A55 -> SB26YUNC4-H180-3 | B18: ='Tabla general'!B55 -> Sauvignon Blanc | C18: ='Tabla general'!C55 -> Curicó | D18: ='Tabla general'!D55 -> YUNGAY | E18: ='Tabla general'!E55 -> 4 | F18: ='Tabla general'!F55 -> 180 | G18: ='Tabla general'!G55 -> 3 | H18: ='Tabla general'!H55 -> 46058 | ... J18: ='Tabla general'!J55 -> 13.5 | K18: ='Tabla general'!K55*0.49 -> 12.25 | L18: ='Tabla general'!L55*1.53 -> 18.7425 | M18: ='Tabla general'!N55/200 -> 1.7635
A19: ='Tabla general'!A56 -> SB26YUNC4-H180-4 | B19: ='Tabla general'!B56 -> Sauvignon Blanc | C19: ='Tabla general'!C56 -> Curicó | D19: ='Tabla general'!D56 -> YUNGAY | E19: ='Tabla general'!E56 -> 4 | F19: ='Tabla general'!F56 -> 180 | G19: ='Tabla general'!G56 -> 4 | H19: ='Tabla general'!H56 -> 46065 | ... J19: ='Tabla general'!J56 -> 15.4 | K19: ='Tabla general'!K56*0.49 -> 9.7314 | L19: ='Tabla general'!L56*1.53 -> 14.889042 | M19: ='Tabla general'!N56/200 -> 1.836
A20: ='Tabla general'!A57 -> SB26YUNC4-H180-5 | B20: ='Tabla general'!B57 -> Sauvignon Blanc | C20: ='Tabla general'!C57 -> Curicó | D20: ='Tabla general'!D57 -> YUNGAY | E20: ='Tabla general'!E57 -> 4 | F20: ='Tabla general'!F57 -> 180 | G20: ='Tabla general'!G57 -> 5 | H20: ='Tabla general'!H57 -> 46072 | ... J20: ='Tabla general'!J57 -> 17.6 | K20: ='Tabla general'!K57*0.49 -> 7.2618 | L20: ='Tabla general'!L57*1.53 -> 11.110554 | M20: ='Tabla general'!N57/200 -> 1.905
A21: ='Tabla general'!A58 -> SB26YUNC4-H180-6 | B21: ='Tabla general'!B58 -> Sauvignon Blanc | C21: ='Tabla general'!C58 -> Curicó | D21: ='Tabla general'!D58 -> YUNGAY | E21: ='Tabla general'!E58 -> 4 | F21: ='Tabla general'!F58 -> 180 | G21: ='Tabla general'!G58 -> 6 | H21: ='Tabla general'!H58 -> 46079 | ... J21: ='Tabla general'!J58 -> 19.1 | K21: ='Tabla general'!K58*0.49 -> 6.419 | L21: ='Tabla general'!L58*1.53 -> 9.82107 | M21: ='Tabla general'!N58/200 -> 1.9745
A22: ='Tabla general'!A59 -> SB26YUNC4-H180-7 | B22: ='Tabla general'!B59 -> Sauvignon Blanc | C22: ='Tabla general'!C59 -> Curicó | D22: ='Tabla general'!D59 -> YUNGAY | E22: ='Tabla general'!E59 -> 4 | F22: ='Tabla general'!F59 -> 180 | G22: ='Tabla general'!G59 -> 7 | H22: ='Tabla general'!H59 -> 46086 | ... J22: ='Tabla general'!J59 -> 19.3 | K22: ='Tabla general'!K59*0.49 -> 6.3847 | L22: ='Tabla general'!L59*1.53 -> 9.768591 | M22: ='Tabla general'!N59/200 -> 2.043
A23: ='Tabla general'!A60 -> SB26YUNC4-H180-8 | B23: ='Tabla general'!B60 -> Sauvignon Blanc | C23: ='Tabla general'!C60 -> Curicó | D23: ='Tabla general'!D60 -> YUNGAY | E23: ='Tabla general'!E60 -> 4 | F23: ='Tabla general'!F60 -> 180 | G23: ='Tabla general'!G60 -> 8 | H23: ='Tabla general'!H60 -> 46094 | ... J23: ='Tabla general'!J60 -> 21.1 | K23: ='Tabla general'!K60*0.49 -> 3.5966 | L23: ='Tabla general'!L60*1.53 -> 5.502798 | M23: ='Tabla general'!N60/200 -> 2.002
A24: ='Tabla general'!A61 -> SB26YUNC4-H180-9 | B24: ='Tabla general'!B61 -> Sauvignon Blanc | C24: ='Tabla general'!C61 -> Curicó | D24: ='Tabla general'!D61 -> YUNGAY | E24: ='Tabla general'!E61 -> 4 | F24: ='Tabla general'!F61 -> 180 | G24: ='Tabla general'!G61 -> 9 | H24: ='Tabla general'!H61 -> 46100 | ... J24: ='Tabla general'!J61 -> 20.8 | K24: ='Tabla general'!K61*0.49 -> 5.2136 | L24: ='Tabla general'!L61*1.53 -> 7.976808 | M24: ='Tabla general'!N61/200 -> 1.95
A25: ='Tabla general'!A62 -> SB26YUNC4-H180-10 | B25: ='Tabla general'!B62 -> Sauvignon Blanc | C25: ='Tabla general'!C62 -> Curicó | D25: ='Tabla general'!D62 -> YUNGAY | E25: ='Tabla general'!E62 -> 4 | F25: ='Tabla general'!F62 -> 180 | G25: ='Tabla general'!G62 -> 10 | H25: ='Tabla general'!H62 -> - | ... J25: ='Tabla general'!J62 -> 18.7 | K25: ='Tabla general'!K62*0.49 -> 5.6056 | L25: ='Tabla general'!L62*1.53 -> 8.576568 | M25: ='Tabla general'!N62/200 -> 1.8545
A26: ='Tabla general'!A63 -> SB26YUNC4-H180-11 | B26: ='Tabla general'!B63 -> Sauvignon Blanc | C26: ='Tabla general'!C63 -> Curicó | D26: ='Tabla general'!D63 -> YUNGAY | E26: ='Tabla general'!E63 -> 4 | F26: ='Tabla general'!F63 -> 180 | G26: ='Tabla general'!G63 -> 11 | H26: ='Tabla general'!H63 -> 46114 | ... J26: ='Tabla general'!J63 -> 21.7 | K26: ='Tabla general'!K63*0.49 -> 5.3998 | L26: ='Tabla general'!L63*1.53 -> 8.261694 | M26: ='Tabla general'!N63/200 -> 1.956
A27: ='Tabla general'!A64 -> SB26YUNC4-H180-12 | B27: ='Tabla general'!B64 -> Sauvignon Blanc | C27: ='Tabla general'!C64 -> Curicó | D27: ='Tabla general'!D64 -> YUNGAY | E27: ='Tabla general'!E64 -> 4 | F27: ='Tabla general'!F64 -> 180 | G27: ='Tabla general'!G64 -> 12 | H27: ='Tabla general'!H64 -> 46121 | ... J27: ='Tabla general'!J64 -> 19.4 | K27: ='Tabla general'!K64*0.49 -> 5.2381 | L27: ='Tabla general'!L64*1.53 -> 8.014293 | M27: ='Tabla general'!N64/200 -> 1.9145
A28: ='Tabla general'!A65 -> SB26YUNC4-H180-13 | B28: ='Tabla general'!B65 -> Sauvignon Blanc | C28: ='Tabla general'!C65 -> Curicó | D28: ='Tabla general'!D65 -> YUNGAY | E28: ='Tabla general'!E65 -> 4 | F28: ='Tabla general'!F65 -> 180 | G28: ='Tabla general'!G65 -> 13 | H28: ='Tabla general'!H65 -> 46127 | ... J28: ='Tabla general'!J65 -> 21.4 | K28: ='Tabla general'!K65*0.49 -> 5.1548 | L28: ='Tabla general'!L65*1.53 -> 7.886844 | M28: ='Tabla general'!N65/200 -> 2.0445

Sheet SB-Rauco
A2: 2025
A3: Id. original muestra | B3: Variedad | C3: Valles | D3: Fundo | E3: Cuartel | F3: Hilera | G3: N°muestra | H3: Fecha | I3: pH | J3: Brix | K3: Acidez Sulfúrica | L3: Acidez Tartárica | M3: Peso baya
A4: SB25RAUC7-H9-1 | B4: Sauvignon Blanc | C4: Curicó | D4: RAUCO | E4: 7 | F4: 9 | G4: =_xlfn.TEXTAFTER(A4, "-", 2) -> 1 | H4: 45680 | I4: 2.53 | J4: 9.4 | K4: 17.8556 | L4: 27.319 | M4: 0.75
A5: SB25RAUC7-H9-2 | B5: Sauvignon Blanc | C5: Curicó | D5: RAUCO | E5: 7 | F5: 9 | G5: =_xlfn.TEXTAFTER(A5, "-", 2) -> 2 | H5: 45684 | I5: 2.57 | J5: 12.1 | K5: 14.7196 | L5: 22.521 | M5: 0.78
A6: SB25RAUC7-H9-3 | B6: Sauvignon Blanc | C6: Curicó | D6: RAUCO | E6: 7 | F6: 9 | G6: =_xlfn.TEXTAFTER(A6, "-", 2) -> 3 | H6: 45691 | I6: 2.74 | J6: 15.4 | K6: 9.2414 | L6: 14.1393 | M6: 0.91
A7: SB25RAUC7-H9-4 | B7: Sauvignon Blanc | C7: Curicó | D7: RAUCO | E7: 7 | F7: 9 | G7: =_xlfn.TEXTAFTER(A7, "-", 2) -> 4 | H7: 45698 | I7: 2.9 | J7: 17.7 | K7: 6.076 | L7: 9.2953 | M7: 1.14
A8: SB25RAUC7-H9-5 | B8: Sauvignon Blanc | C8: Curicó | D8: RAUCO | E8: 7 | F8: 9 | G8: =_xlfn.TEXTAFTER(A8, "-", 2) -> 5 | H8: 45705 | I8: 3.09 | J8: 19.6 | K8: 4.4688 | L8: 6.8373 | M8: 1.23
A9: SB25RAUC7-H9-6 | B9: Sauvignon Blanc | C9: Curicó | D9: RAUCO | E9: 7 | F9: 9 | G9: =_xlfn.TEXTAFTER(A9, "-", 2) -> 6 | H9: 45713 | I9: 3.29 | J9: 22 | K9: 3.9494 | L9: 6.0426 | M9: 1.31
A10: SB25RAUC7-H9-7 | B10: Sauvignon Blanc | C10: Curicó | D10: RAUCO | E10: 7 | F10: 9 | G10: =_xlfn.TEXTAFTER(A10, "-", 2) -> 7 | H10: 45719 | I10: 3.38 | J10: 22.9 | K10: 3.3124 | L10: 5.068 | M10: 1.4
A11: SB25RAUC7-H9-8 | B11: Sauvignon Blanc | C11: Curicó | D11: RAUCO | E11: 7 | F11: 9 | G11: =_xlfn.TEXTAFTER(A11, "-", 2) -> 8 | H11: 45728 | I11: 3.51 | J11: 24.4 | K11: 2.8028 | L11: 4.2883 | M11: 1.58
A12: SB25RAUC7-H9-9 | B12: Sauvignon Blanc | C12: Curicó | D12: RAUCO | E12: 7 | F12: 9 | G12: =_xlfn.TEXTAFTER(A12, "-", 2) -> 9 | H12: 45734 | I12: 3.66 | J12: 25.3 | K12: 2.7489 | L12: 4.2058 | M12: 1.48
A14: 2026
A15: Id. original muestra | B15: Variedad | C15: Valles | D15: Fundo | E15: Cuartel | F15: Hilera | G15: N°muestra | H15: Fecha | I15: pH | J15: Brix | K15: Acidez Sulfúrica | L15: Acidez Tartárica | M15: Peso baya
A16: ='Tabla general'!A66 -> SB26RAUC7-H9-1 | B16: ='Tabla general'!B66 -> Sauvignon Blanc | C16: ='Tabla general'!C66 -> Curicó | D16: ='Tabla general'!D66 -> RAUCO | E16: ='Tabla general'!E66 -> 7 | F16: ='Tabla general'!F66 -> 9 | G16: ='Tabla general'!G66 -> 1 | H16: ='Tabla general'!H66 -> 46044 | ... J16: ='Tabla general'!J66 -> 13.6 | K16: ='Tabla general'!K66*0.49 -> 12.2745 | L16: ='Tabla general'!L66*1.53 -> 18.779985 | M16: ='Tabla general'!N66/200 -> 0.92965
A17: ='Tabla general'!A67 -> SB26RAUC7-H9-2 | B17: ='Tabla general'!B67 -> Sauvignon Blanc | C17: ='Tabla general'!C67 -> Curicó | D17: ='Tabla general'!D67 -> RAUCO | E17: ='Tabla general'!E67 -> 7 | F17: ='Tabla general'!F67 -> 9 | G17: ='Tabla general'!G67 -> 2 | H17: ='Tabla general'!H67 -> 46050 | ... J17: ='Tabla general'!J67 -> 16.3 | K17: ='Tabla general'!K67*0.49 -> 6.076 | L17: ='Tabla general'!L67*1.53 -> 9.29628 | M17: ='Tabla general'!N67/200 -> 1.07795
A18: ='Tabla general'!A68 -> SB26RAUC7-H9-3 | B18: ='Tabla general'!B68 -> Sauvignon Blanc | C18: ='Tabla general'!C68 -> Curicó | D18: ='Tabla general'!D68 -> RAUCO | E18: ='Tabla general'!E68 -> 7 | F18: ='Tabla general'!F68 -> 9 | G18: ='Tabla general'!G68 -> 3 | H18: ='Tabla general'!H68 -> 46057 | ... J18: ='Tabla general'!J68 -> 17.5 | K18: ='Tabla general'!K68*0.49 -> 5.1352 | L18: ='Tabla general'!L68*1.53 -> 7.856856 | M18: ='Tabla general'!N68/200 -> 1.378
A19: ='Tabla general'!A69 -> SB26RAUC7-H9-4 | B19: ='Tabla general'!B69 -> Sauvignon Blanc | C19: ='Tabla general'!C69 -> Curicó | D19: ='Tabla general'!D69 -> RAUCO | E19: ='Tabla general'!E69 -> 7 | F19: ='Tabla general'!F69 -> 9 | G19: ='Tabla general'!G69 -> 4 | H19: ='Tabla general'!H69 -> 46064 | ... J19: ='Tabla general'!J69 -> 19.4 | K19: ='Tabla general'!K69*0.49 -> 4.5276 | L19: ='Tabla general'!L69*1.53 -> 6.927228 | M19: ='Tabla general'!N69/200 -> 1.4265
A20: ='Tabla general'!A70 -> SB26RAUC7-H9-5 | B20: ='Tabla general'!B70 -> Sauvignon Blanc | C20: ='Tabla general'!C70 -> Curicó | D20: ='Tabla general'!D70 -> RAUCO | E20: ='Tabla general'!E70 -> 7 | F20: ='Tabla general'!F70 -> 9 | G20: ='Tabla general'!G70 -> 5 | H20: ='Tabla general'!H70 -> 46071 | ... J20: ='Tabla general'!J70 -> 21.1 | K20: ='Tabla general'!K70*0.49 -> 3.5378 | L20: ='Tabla general'!L70*1.53 -> 5.412834 | M20: ='Tabla general'!N70/200 -> 1.4425
A21: ='Tabla general'!A71 -> SB26RAUC7-H9-6 | B21: ='Tabla general'!B71 -> Sauvignon Blanc | C21: ='Tabla general'!C71 -> Curicó | D21: ='Tabla general'!D71 -> RAUCO | E21: ='Tabla general'!E71 -> 7 | F21: ='Tabla general'!F71 -> 9 | G21: ='Tabla general'!G71 -> 6 | H21: ='Tabla general'!H71 -> 46078 | ... J21: ='Tabla general'!J71 -> 23.4 | K21: ='Tabla general'!K71*0.49 -> 3.087 | L21: ='Tabla general'!L71*1.53 -> 4.72311 | M21: ='Tabla general'!N71/200 -> 1.3055
A22: ='Tabla general'!A72 -> SB26RAUC7-H9-7 | B22: ='Tabla general'!B72 -> Sauvignon Blanc | C22: ='Tabla general'!C72 -> Curicó | D22: ='Tabla general'!D72 -> RAUCO | E22: ='Tabla general'!E72 -> 7 | F22: ='Tabla general'!F72 -> 9 | G22: ='Tabla general'!G72 -> 7 | H22: ='Tabla general'!H72 -> 46085 | ... J22: ='Tabla general'!J72 -> 24.3 | K22: ='Tabla general'!K72*0.49 -> 3.0772 | L22: ='Tabla general'!L72*1.53 -> 4.708116 | M22: ='Tabla general'!N72/200 -> 1.3285
A23: ='Tabla general'!A73 -> SB26RAUC7-H9-8 | B23: ='Tabla general'!B73 -> Sauvignon Blanc | C23: ='Tabla general'!C73 -> Curicó | D23: ='Tabla general'!D73 -> RAUCO | E23: ='Tabla general'!E73 -> 7 | F23: ='Tabla general'!F73 -> 9 | G23: ='Tabla general'!G73 -> 8 | H23: ='Tabla general'!H73 -> 46092 | ... J23: ='Tabla general'!J73 -> 24.9 | K23: ='Tabla general'!K73*0.49 -> 2.9988 | L23: ='Tabla general'!L73*1.53 -> 4.588164 | M23: ='Tabla general'!N73/200 -> 1.2315
A24: ='Tabla general'!A74 -> SB26RAUC7-H9-9 | B24: ='Tabla general'!B74 -> Sauvignon Blanc | C24: ='Tabla general'!C74 -> Curicó | D24: ='Tabla general'!D74 -> RAUCO | E24: ='Tabla general'!E74 -> 7 | F24: ='Tabla general'!F74 -> 9 | G24: ='Tabla general'!G74 -> 9 | H24: ='Tabla general'!H74 -> 46099 | ... J24: ='Tabla general'!J74 -> 25.8 | K24: ='Tabla general'!K74*0.49 -> 2.352 | L24: ='Tabla general'!L74*1.53 -> 3.59856 | M24: ='Tabla general'!N74/200 -> 1.078
A25: ='Tabla general'!A75 -> SB26RAUC7-H9-10 | B25: ='Tabla general'!B75 -> Sauvignon Blanc | C25: ='Tabla general'!C75 -> Curicó | D25: ='Tabla general'!D75 -> RAUCO | E25: ='Tabla general'!E75 -> 7 | F25: ='Tabla general'!F75 -> 9 | G25: ='Tabla general'!G75 -> 10 | H25: ='Tabla general'!H75 -> 46105 | ... J25: ='Tabla general'!J75 -> 25.4 | K25: ='Tabla general'!K75*0.49 -> 2.0874 | L25: ='Tabla general'!L75*1.53 -> 3.193722 | M25: ='Tabla general'!N75/200 -> 1.529
